Workbook
Name EF: "Button 99"

Sheet ESTRUCTURA FINANCIERA
A1: Carga de datos del del Balance General
A3: ESTRUCTURA FINANCIERA
A5: BALANCE GENERAL
A6: (Expresado en pesos Dominicanos DOP)
A8: CONCEPTOS | B8: FECHA | C8: % | D8: FECHA | E8: % | F8: FECHA | G8: %
B9: 45657 | D9: 45291 | F9: 44926
A10: EFECTIVO EN CAJA Y BANCOS | B10: 15121187075 | C10: =IF(B10=0," ",(B10/B$30)*100) -> 21.817592 | D10: 12350077221 | E10: =IF(D10=0," ",(D10/D$30)*100) -> 22.06467 | F10: 14608256735 | G10: =IF(F10=0," ",(F10/F$30)*100) -> 28.492454
A11: INVERS. FINANCIERAS TEMPORALES | B11: 13694398052 | C11: =IF(B11=0," ",(B11/B$30)*100) -> 19.75895 | D11: 11492210312 | E11: =IF(D11=0," ",(D11/D$30)*100) -> 20.532003 | F11: 8777835122 | G11: =IF(F11=0," ",(F11/F$30)*100) -> 17.120596
A12: CUENTAS POR COBRAR COMERCIALES NETAS | B12: 38968370735 | C12: =IF(B12=0," ",(B12/B$30)*100) -> 56.22548 | D12: 30829664914 | E12: =IF(D12=0," ",(D12/D$30)*100) -> 55.080334 | F12: 26753444573 | G12: =IF(F12=0," ",(F12/F$30)*100) -> 52.180852
A13: DERIVADOS Y CONTRATOS DE COMPRA VENTA | B13: 0 | C13: =IF(B13=0," ",(B13/B$30)*100) | D13: 0 | E13: =IF(D13=0," ",(D13/D$30)*100) | F13: 32556160 | G13: =IF(F13=0," ",(F13/F$30)*100) -> 0.06349867
A14: CUENTAS POR COBRAR GRUPO | B14: 472224220 | C14: =IF(B14=0," ",(B14/B$30)*100) -> 0.6813483 | D14: 233832409 | E14: =IF(D14=0," ",(D14/D$30)*100) -> 0.4177654 | F14: 128742576 | G14: =IF(F14=0," ",(F14/F$30)*100) -> 0.25110401
A15: BIENES RECIBIDOS EN RECUPERACION | B15: 19821699 | C15: =IF(B15=0," ",(B15/B$30)*100) -> 0.028599721 | D15: 76584927 | E15: =IF(D15=0," ",(D15/D$30)*100) -> 0.13682677 | F15: 113174393 | G15: =IF(F15=0," ",(F15/F$30)*100) -> 0.22073928
A16: PREPAGADOS | B16: 0 | C16: =IF(B16=0," ",(B16/B$30)*100) | D16: 0 | E16: =IF(D16=0," ",(D16/D$30)*100) | F16: 0 | G16: =IF(F16=0," ",(F16/F$30)*100)
A17: ACTIVO CIRCULANTE | B17: =SUM(B10:B16) -> 68276001781 | C17: =IF(B17=0," ",(B17/B$30)*100) -> 98.51197 | D17: =SUM(D10:D16) -> 54982369783 | E17: =IF(D17=0," ",(D17/D$30)*100) -> 98.2316 | F17: =SUM(F10:F16) -> 50414009559 | G17: =IF(F17=0," ",(F17/F$30)*100) -> 98.329243
A18: TERRENOS | B18: 0 | C18: =IF(B18=0," ",(B18/B$30)*100) | D18: 0 | E18: =IF(D18=0," ",(D18/D$30)*100) | F18: 0 | G18: =IF(F18=0," ",(F18/F$30)*100)
A19: EDIFICIOS E INSTALACIONES | B19: 0 | C19: =IF(B19=0," ",(B19/B$30)*100) | D19: 0 | E19: =IF(D19=0," ",(D19/D$30)*100) | F19: 0 | G19: =IF(F19=0," ",(F19/F$30)*100)
A20: MAQUINARIAS Y EQUIPOS | B20: 397705745 | C20: =IF(B20=0," ",(B20/B$30)*100) -> 0.57382939 | D20: 342410735 | E20: =IF(D20=0," ",(D20/D$30)*100) -> 0.61175163 | F20: 272815658 | G20: =IF(F20=0," ",(F20/F$30)*100) -> 0.53210918
A21: OTROS ACTIVOS FIJOS MATERIALES | B21: 0 | C21: =IF(B21=0," ",(B21/B$30)*100) | D21: 0 | E21: =IF(D21=0," ",(D21/D$30)*100) | F21: 0 | G21: =IF(F21=0," ",(F21/F$30)*100)
A22: AMORTIZACION (DEP.) ACUMULADA. | B22: 0 | C22: =IF(B22=0," ",(B22/B$30)*100) | D22: 0 | E22: =IF(D22=0," ",(D22/D$30)*100) | F22: 0 | G22: =IF(F22=0," ",(F22/F$30)*100)
A23: ACTIVOS FIJOS MATERIALES NETOS | B23: =+B18+B19+B20+B21-B22 -> 397705745 | C23: =IF(B23=0," ",(B23/B$30)*100) -> 0.57382939 | D23: =+D18+D19+D20+D21-D22 -> 342410735 | E23: =IF(D23=0," ",(D23/D$30)*100) -> 0.61175163 | F23: =+F18+F19+F20+F21-F22 -> 272815658 | G23: =IF(F23=0," ",(F23/F$30)*100) -> 0.53210918
A24: ACTIVO INTANGIBLE NETO | B24: 0 | C24: =IF(B24=0," ",(B24/B$30)*100) | D24: 0 | E24: =IF(D24=0," ",(D24/D$30)*100) | F24: 0 | G24: =IF(F24=0," ",(F24/F$30)*100)
A25: ACTIVO FINANCIERO A L.P. | B25: 0 | C25: =IF(B25=0," ",(B25/B$30)*100) | D25: 0 | E25: =IF(D25=0," ",(D25/D$30)*100) | F25: 0 | G25: =IF(F25=0," ",(F25/F$30)*100)
A26: PRESTAMOS AL GRUPO A L.P. | B26: 0 | C26: =IF(B26=0," ",(B26/B$30)*100) | D26: 0 | E26: =IF(D26=0," ",(D26/D$30)*100) | F26: 0 | G26: =IF(F26=0," ",(F26/F$30)*100) | I26: =B30 -> 69307315746
A27: CARGOS DIFERIDOS A L.P. | B27: 633608220 | C27: =IF(B27=0," ",(B27/B$30)*100) -> 0.91420107 | D27: 647401492 | E27: =IF(D27=0," ",(D27/D$30)*100) -> 1.1566487 | F27: 583791740 | G27: =IF(F27=0," ",(F27/F$30)*100) -> 1.1386478
A28: OTROS ACTIVOS A L.P. | B28: 0 | C28: =IF(B28=0," ",(B28/B$30)*100) | D28: 0 | E28: =IF(D28=0," ",(D28/D$30)*100) | F28: 0 | G28: =IF(F28=0," ",(F28/F$30)*100)
A29: INMOVILIZADO NETO | B29: =SUM(B23:B28) -> 1031313965 | C29: =IF(B29=0," ",(B29/B$30)*100) -> 1.4880305 | D29: =SUM(D23:D28) -> 989812227 | E29: =IF(D29=0," ",(D29/D$30)*100) -> 1.7684003 | F29: =SUM(F23:F28) -> 856607398 | G29: =IF(F29=0," ",(F29/F$30)*100) -> 1.670757
A30: TOTAL ACTIVOS | B30: =B17+B29 -> 69307315746 | C30: =IF(B30=0," ",(B30/B$30)*100) -> 100 | D30: =D17+D29 -> 55972182010 | E30: =IF(D30=0," ",(D30/D$30)*100) -> 100 | F30: =F17+F29 -> 51270616957 | G30: =IF(F30=0," ",(F30/F$30)*100) -> 100
A31: BANCOS A CORTO PLAZO (Deposito al Publico) | B31: 38558604541 | C31: =IF(B31=0," ",(B31/B$30)*100) -> 55.634249 | D31: 32056991117 | E31: =IF(D31=0," ",(D31/D$30)*100) -> 57.273077 | F31: 27982022945 | G31: =IF(F31=0," ",(F31/F$30)*100) -> 54.577114
A32: DEPOSITOS A ENTIDADES FINANCIERAS | B32: 11149572080 | C32: =IF(B32=0," ",(B32/B$30)*100) -> 16.08715 | D32: 10212015251 | E32: =IF(D32=0," ",(D32/D$30)*100) -> 18.244805 | F32: 8678464021 | G32: =IF(F32=0," ",(F32/F$30)*100) -> 16.926779
A33: FONDOS TOMADOS A PRESTAMOS | B33: 11275067827 | C33: =IF(B33=0," ",(B33/B$30)*100) -> 16.268222 | D33: 6862777984 | E33: =IF(D33=0," ",(D33/D$30)*100) -> 12.261051 | F33: 9873890872 | G33: =IF(F33=0," ",(F33/F$30)*100) -> 19.258381
A34: CTAS A PAGAR AL GRUPO C.P. | B34: 0 | C34: =IF(B34=0," ",(B34/B$30)*100) | D34: 0 | E34: =IF(D34=0," ",(D34/D$30)*100) | F34: 0 | G34: =IF(F34=0," ",(F34/F$30)*100)
A35: ANTICIPOS DE CLIENTES | B35: 0 | C35: =IF(B35=0," ",(B35/B$30)*100) | D35: 0 | E35: =IF(D35=0," ",(D35/D$30)*100) | F35: 0 | G35: =IF(F35=0," ",(F35/F$30)*100)
A36: ADMON. PUBLICA A C.P./IMPTOS. | B36: 0 | C36: =IF(B36=0," ",(B36/B$30)*100) | D36: 0 | E36: =IF(D36=0," ",(D36/D$30)*100) | F36: 0 | G36: =IF(F36=0," ",(F36/F$30)*100)
A37: CREDITOS DIFERIDOS A C.P. | B37: 0 | C37: =IF(B37=0," ",(B37/B$30)*100) | D37: 0 | E37: =IF(D37=0," ",(D37/D$30)*100) | F37: 0 | G37: =IF(F37=0," ",(F37/F$30)*100)
A38: OTROS PASIVOS CORRIENTES | B38: 0 | C38: =IF(B38=0," ",(B38/B$30)*100) | D38: 0 | E38: =IF(D38=0," ",(D38/D$30)*100) | F38: 0 | G38: =IF(F38=0," ",(F38/F$30)*100)
A39: PASIVO CIRCULANTE | B39: =SUM(B31:B38) -> 60983244448 | C39: =IF(B39=0," ",(B39/B$30)*100) -> 87.989621 | D39: =SUM(D31:D38) -> 49131784352 | E39: =IF(D39=0," ",(D39/D$30)*100) -> 87.778933 | F39: =SUM(F31:F38) -> 46534377838 | G39: =IF(F39=0," ",(F39/F$30)*100) -> 90.762274
A40: OTROS PASIVOS A L.P. | B40: 758020942 | C40: =IF(B40=0," ",(B40/B$30)*100) -> 1.0937099 | D40: 657467927 | E40: =IF(D40=0," ",(D40/D$30)*100) -> 1.1746334 | F40: 440657974 | G40: =IF(F40=0," ",(F40/F$30)*100) -> 0.85947469
A41: OBLIGACIONES ASIMILARES DE CAPITAL | B41: 2867148772 | C41: =IF(B41=0," ",(B41/B$30)*100) -> 4.1368631 | D41: 2096227964 | E41: =IF(D41=0," ",(D41/D$30)*100) -> 3.7451246 | F41: 1397212790 | G41: =IF(F41=0," ",(F41/F$30)*100) -> 2.7251726
A42: CTAS. POR PAGAR A L.P. | B42: 0 | C42: =IF(B42=0," ",(B42/B$30)*100) | D42: 0 | E42: =IF(D42=0," ",(D42/D$30)*100) | F42: 0 | G42: =IF(F42=0," ",(F42/F$30)*100)
A43: BANCOS A LP. | B43: 0 | C43: =IF(B43=0," ",(B43/B$30)*100) | D43: 0 | E43: =IF(D43=0," ",(D43/D$30)*100) | F43: 0 | G43: =IF(F43=0," ",(F43/F$30)*100)
...

Sheet ESTRUCTURA ECONOMICA
A1: Carga de datos del estado de Ganancias y pérdidas
A3: Seleccionar el ciclo temporal de análisis, si es información mesual o anual | B3: Anual
A4: ESTRUCTURA ECONOMICA
A6: ESTADO DE GANANCIAS Y PERDIDAS
A7: (Expresado en pesos Dominicanos DOP)
A8: CONCEPTOS | B8: ='ESTRUCTURA FINANCIERA'!B9 -> 45657 | C8: % | D8: VAR. % | E8: ='ESTRUCTURA FINANCIERA'!D9 -> 45291 | F8: % | G8: ='ESTRUCTURA FINANCIERA'!F9 -> 44926 | H8: %
H9: =IF(G9=0," ",(G9/G$10)*100)
A10: . = INGRESOS TOTALES | B10: 7296960590 | C10: =IF(B10=0," ",(B10/B$10)*100) -> 100 | D10: =IF(B10=0," ",((B10-E10)/E10)*100) -> 20.493229 | E10: 6055909264 | F10: =IF(E10=0," ",(E10/E$10)*100) -> 100 | G10: 4357637360 | H10: =IF(G10=0," ",(G10/G$10)*100) -> 100
A11: . + OTROS INGRESOS OPERACIONALES | B11: 0 | C11: =IF(B11=0," ",(B11/B$10)*100) | D11: =IF(B11=0," ",((B11-E11)/E11)*100) | E11: 0 | F11: =IF(E11=0," ",(E11/E$10)*100) | G11: 0 | H11: =IF(G11=0," ",(G11/G$10)*100)
A12: CONSUMOS(GASTOS FINANCIEROS) | B12: 4514441475 | C12: =IF(B12=0," ",(B12/B$10)*100) -> 61.867423 | D12: =IF(B12=0," ",((B12-E12)/E12)*100) -> 22.554422 | E12: 3683621861 | F12: =IF(E12=0," ",(E12/E$10)*100) -> 60.8269 | G12: 2600138001 | H12: =IF(G12=0," ",(G12/G$10)*100) -> 59.668526
A13: RESULTADOS NETO DE ACTIVOS FINANCIEROS A VALOR RAZONABLE | B13: 0 | C13: =IF(B13=0," ",(B13/B$10)*100) | D13: =IF(B13=0," ",((B13-E13)/E13)*100) | E13: 15174160 | F13: =IF(E13=0," ",(E13/E$10)*100) -> 0.25056782 | G13: 141947140 | H13: =IF(G13=0," ",(G13/G$10)*100) -> 3.2574335
A14: OTROS GASTOS | B14: 0 | C14: =IF(B14=0," ",(B14/B$10)*100) | D14: =IF(B14=0," ",((B14-E14)/E14)*100) | E14: 0 | F14: =IF(E14=0," ",(E14/E$10)*100) | G14: 0 | H14: =IF(G14=0," ",(G14/G$10)*100)
A15: . - COSTO DE VENTAS | B15: =SUM(B12:B14) -> 4514441475 | C15: =IF(B15=0," ",(B15/B$10)*100) -> 61.867423 | D15: =IF(B15=0," ",((B15-E15)/E15)*100) -> 22.051647 | E15: =SUM(E12:E14) -> 3698796021 | F15: =IF(E15=0," ",(E15/E$10)*100) -> 61.077468 | G15: =SUM(G12:G14) -> 2742085141 | H15: =IF(G15=0," ",(G15/G$10)*100) -> 62.92596
A16: . = UTILIDAD BRUTA EN VENTAS | B16: =B10+B11-B15 -> 2782519115 | C16: =IF(B16=0," ",(B16/B$10)*100) -> 38.132577 | D16: =IF(B16=0," ",((B16-E16)/E16)*100) -> 18.047749 | E16: =E10+E11-E15 -> 2357113243 | F16: =IF(E16=0," ",(E16/E$10)*100) -> 38.922532 | G16: =G10+G11-G15 -> 1615552219 | H16: =IF(G16=0," ",(G16/G$10)*100) -> 37.07404
A17: .- GASTOS DE PERSONAL | B17: 3031088729 | C17: =IF(B17=0," ",(B17/B$10)*100) -> 41.539059 | D17: =IF(B17=0," ",((B17-E17)/E17)*100) -> 18.48639 | E17: 2558174600 | F17: =IF(E17=0," ",(E17/E$10)*100) -> 42.242618 | G17: 1905512351 | H17: =IF(G17=0," ",(G17/G$10)*100) -> 43.728108
A18: .- AMORTIZACION Y DEPRECIACION | B18: 0 | C18: =IF(B18=0," ",(B18/B$10)*100) | D18: =IF(B18=0," ",((B18-E18)/E18)*100) | E18: 0 | F18: =IF(E18=0," ",(E18/E$10)*100) | G18: 0 | H18: =IF(G18=0," ",(G18/G$10)*100)
A19: .- PROVISIONES DEL CIRCULANTE | B19: 1028567054 | C19: =IF(B19=0," ",(B19/B$10)*100) -> 14.095829 | D19: =IF(B19=0," ",((B19-E19)/E19)*100) -> 58.966782 | E19: 647032696 | F19: =IF(E19=0," ",(E19/E$10)*100) -> 10.68432 | G19: 397614455 | H19: =IF(G19=0," ",(G19/G$10)*100) -> 9.1245421
A20: .- OTROS GASTOS OPERATIVOS | B20: 840639663 | C20: =IF(B20=0," ",(B20/B$10)*100) -> 11.520408 | D20: =IF(B20=0," ",((B20-E20)/E20)*100) -> 31.692603 | E20: 638334761 | F20: =IF(E20=0," ",(E20/E$10)*100) -> 10.540692 | G20: 577425378 | H20: =IF(G20=0," ",(G20/G$10)*100) -> 13.250882
A21: . = UTILIDAD NETA EN OPERACIONES | B21: =B16-B17-B18-B19-B20 -> -2117776331 | C21: =IF(B21=0," ",(B21/B$10)*100) -> -29.022718 | D21: =IF(B21=0," ",((B21-E21)/E21)*100) -> 42.474117 | E21: =E16-E17-E18-E19-E20 -> -1486428814 | F21: =IF(E21=0," ",(E21/E$10)*100) -> -24.545097 | G21: =G16-G17-G18-G19-G20 -> -1264999965 | H21: =IF(G21=0," ",(G21/G$10)*100) -> -29.029491
A22: INGRESOS FINANCIEROS | B22: =42531535+2350725381+407067686 -> 2800324602 | C22: =IF(B22=0," ",(B22/B$10)*100) -> 38.376589 | D22: =IF(B22=0," ",((B22-E22)/E22)*100) -> 29.440264 | E22: =42817313+2017947711+102645735 -> 2163410759 | F22: =IF(E22=0," ",(E22/E$10)*100) -> 35.723963 | G22: =137283183+1600634682+60518023 -> 1798435888 | H22: =IF(G22=0," ",(G22/G$10)*100) -> 41.270894
A23: EGRESOS FINANCIEROS | B23: 0 | C23: =IF(B23=0," ",(B23/B$10)*100) | D23: =IF(B23=0," ",((B23-E23)/E23)*100) | E23: 0 | F23: =IF(E23=0," ",(E23/E$10)*100) | H23: =IF(G23=0," ",(G23/G$10)*100)
A24: RESULTADO EN MONEDA EXT. | B24: 0 | C24: =IF(B24=0," ",(B24/B$10)*100) | D24: =IF(B24=0," ",((B24-E24)/E24)*100) | E24: 0 | F24: =IF(E24=0," ",(E24/E$10)*100) | G24: 0 | H24: =IF(G24=0," ",(G24/G$10)*100)
A25: RESULTADO MONETARIO | B25: 0 | C25: =IF(B25=0," ",(B25/B$10)*100) | D25: =IF(B25=0," ",((B25-E25)/E25)*100) | E25: 0 | F25: =IF(E25=0," ",(E25/E$10)*100) | G25: 0 | H25: =IF(G25=0," ",(G25/G$10)*100)
A26: .+/- COSTO INTEGRAL DE FINANCIAMIENTO | B26: =B22-B23+B24+B25 -> 2800324602 | C26: =IF(B26=0," ",(B26/B$10)*100) -> 38.376589 | D26: =IF(B26=0," ",((B26-E26)/E26)*100) -> 29.440264 | E26: =E22-E23+E24+E25 -> 2163410759 | F26: =IF(E26=0," ",(E26/E$10)*100) -> 35.723963 | G26: =G22-G23+G24+G25 -> 1798435888 | H26: =IF(G26=0," ",(G26/G$10)*100) -> 41.270894
A27: . = RESULTADO ACTIVIDADES ORDINARIAS | B27: =B21+B26 -> 682548271 | C27: =IF(B27=0," ",(B27/B$10)*100) -> 9.3538709 | D27: =IF(B27=0," ",((B27-E27)/E27)*100) -> 0.82222665 | E27: =E21+E26 -> 676981945 | F27: =IF(E27=0," ",(E27/E$10)*100) -> 11.178865 | G27: =G21+G26 -> 533435923 | H27: =IF(G27=0," ",(G27/G$10)*100) -> 12.241402
A28: .+/- RESULTADOS EXTRAORDINARIOS | B28: 0 | C28: =IF(B28=0," ",(B28/B$10)*100) | D28: =IF(B28=0," ",((B28-E28)/E28)*100) | E28: 0 | F28: =IF(E28=0," ",(E28/E$10)*100) | G28: 0 | H28: =IF(G28=0," ",(G28/G$10)*100)
A29: .= BENEFICIO ANTES DE IMPTOS. | B29: =B27+B28 -> 682548271 | C29: =IF(B29=0," ",(B29/B$10)*100) -> 9.3538709 | D29: =IF(B29=0," ",((B29-E29)/E29)*100) -> 0.82222665 | E29: =E27+E28 -> 676981945 | F29: =IF(E29=0," ",(E29/E$10)*100) -> 11.178865 | G29: =G27+G28 -> 533435923 | H29: =IF(G29=0," ",(G29/G$10)*100) -> 12.241402
A30: .- IMPUESTOS | B30: 59474126 | C30: =IF(B30=0," ",(B30/B$10)*100) -> 0.81505341 | D30: =IF(B30=0," ",((B30-E30)/E30)*100) -> 53.884563 | E30: 38648533 | F30: =IF(E30=0," ",(E30/E$10)*100) -> 0.63819538 | G30: 8968137 | H30: =IF(G30=0," ",(G30/G$10)*100) -> 0.20580274
A31: .= BENEFICIO NETO | B31: =B29-B30 -> 623074145 | C31: =IF(B31=0," ",(B31/B$10)*100) -> 8.5388175 | D31: =IF(B31=0," ",((B31-E31)/E31)*100) -> -2.3904854 | E31: =E29-E30 -> 638333412 | F31: =IF(E31=0," ",(E31/E$10)*100) -> 10.54067 | G31: =G29-G30 -> 524467786 | H31: =IF(G31=0," ",(G31/G$10)*100) -> 12.0356
A32: DIVIDENDOS | B32: 0 | C32: =IF(B32=0," ",(B32/B$10)*100) | D32: =IF(B32=0," ",((B32-E32)/E32)*100) | E32: 0 | F32: =IF(E32=0," ",(E32/E$10)*100) | G32: 0 | H32: =IF(G32=0," ",(G32/G$10)*100)
A33: INTERESES MINORITARIOS | B33: 0 | C33: =IF(B33=0," ",(B33/B$10)*100) | D33: =IF(B33=0," ",((B33-E33)/E33)*100) | E33: 0 | F33: =IF(E33=0," ",(E33/E$10)*100) | G33: 0 | H33: =IF(G33=0," ",(G33/G$10)*100)
A34: RESERVAS | B34: 0 | C34: =IF(B34=0," ",(B34/B$10)*100) | D34: =IF(B34=0," ",((B34-E34)/E34)*100) | E34: 0 | F34: =IF(E34=0," ",(E34/E$10)*100) | G34: 0 | H34: =IF(G34=0," ",(G34/G$10)*100) | J34: =B21+532 -> -2117775799
B36: =B31-DUPONT!J14 -> 0 | E36: =E31-DUPONT!J15 -> 0 | G36: =G31-DUPONT!J16 -> 0
B37: =B36/2 -> 0 | E37: =E36/2 -> 0 | G37: =G36/2 -> 0
B38: =B36*2 -> 0 | E38: =E36*2 -> 0 | G38: =G36*2 -> 0
G39: =+G31-524467786 -> 0

Sheet CAPITAL DE TRABAJO
A3: ANALISIS DE LA ESTRUCTURA FINANCIERA
A4: =+'ESTRUCTURA ECONOMICA'!A7 -> (Expresado en pesos Dominicanos DOP)
A5: ANALISIS DEL CAPITAL DE TRABAJO
A6: CONCEPTOS | B6: ='ESTRUCTURA ECONOMICA'!B8 -> 45657 | C6: ='ESTRUCTURA ECONOMICA'!E8 -> 45291 | D6: ='ESTRUCTURA ECONOMICA'!G8 -> 44926 | E6: VARIACION
A7: RECURSOS PROPIOS (PATRIMONIO) | B7: ='ESTRUCTURA FINANCIERA'!B56 -> 4698901584 | C7: ='ESTRUCTURA FINANCIERA'!D56 -> 4086701767 | D7: ='ESTRUCTURA FINANCIERA'!F56 -> 2898368355 | E7: =IF(C7=0," ",((B7-C7)/C7)) -> 0.14980291
A8: .+ PASIVO A LARGO PLAZO | B8: ='ESTRUCTURA FINANCIERA'!B48 -> 3625169714 | C8: ='ESTRUCTURA FINANCIERA'!D48 -> 2753695891 | D8: ='ESTRUCTURA FINANCIERA'!F48 -> 1837870764 | E8: =IF(C8=0," ",((B8-C8)/C8)) -> 0.31647424
A9: .+ INTERESES MINORITARIOS | B9: ='ESTRUCTURA FINANCIERA'!B57 -> 0 | C9: ='ESTRUCTURA FINANCIERA'!D57 -> 0 | D9: ='ESTRUCTURA FINANCIERA'!F57 -> 0 | E9: =IF(C9=0," ",((B9-C9)/C9))
A10: . = RECURSOS PERMANENTES | B10: =SUM(B7:B9) -> 8324071298 | C10: =SUM(C7:C9) -> 6840397658 | D10: =SUM(D7:D9) -> 4736239119 | E10: =IF(C10=0," ",((B10-C10)/C10)) -> 0.21689874
A11: . - INMOVILIZADO NETO | B11: ='ESTRUCTURA FINANCIERA'!B29 -> 1031313965 | C11: ='ESTRUCTURA FINANCIERA'!D29 -> 989812227 | D11: ='ESTRUCTURA FINANCIERA'!F29 -> 856607398 | E11: =IF(C11=0," ",((B11-C11)/C11)) -> 0.0419289
A12: .= CAPITAL DE TRABAJO | B12: =B10-B11 -> 7292757333 | C12: =C10-C11 -> 5850585431 | D12: =D10-D11 -> 3879631721 | E12: =IF(C12=0," ",((B12-C12)/C12)) -> 0.24650044
A13: ACTIVO CIRCULANTE NO FINANCIERO: | B13: =SUM(B14:B18) -> 39460416654 | C13: =SUM(C14:C18) -> 31140082250 | D13: =SUM(D14:D18) -> 27027917702 | E13: =IF(C13=0," ",((B13-C13)/C13)) -> 0.26719051
A14: INVENTARIO NETO | B14: ='ESTRUCTURA FINANCIERA'!B15 -> 19821699 | C14: ='ESTRUCTURA FINANCIERA'!D15 -> 76584927 | D14: ='ESTRUCTURA FINANCIERA'!F15 -> 113174393 | E14: =IF(C14=0," ",((B14-C14)/C14)) -> -0.74118015
A15: CUENTAS A COBRAR COMERCIALES-NETO | B15: ='ESTRUCTURA FINANCIERA'!B12 -> 38968370735 | C15: ='ESTRUCTURA FINANCIERA'!D12 -> 30829664914 | D15: ='ESTRUCTURA FINANCIERA'!F12 -> 26753444573 | E15: =IF(C15=0," ",((B15-C15)/C15)) -> 0.26398943
A16: CUENTAS A COBRAR AL GRUPO A C.P. | B16: ='ESTRUCTURA FINANCIERA'!B13 -> 0 | C16: ='ESTRUCTURA FINANCIERA'!D13 -> 0 | D16: ='ESTRUCTURA FINANCIERA'!F13 -> 32556160 | E16: =IF(C16=0," ",((B16-C16)/C16))
A17: OTRAS CUENTAS POR COBRAR | B17: ='ESTRUCTURA FINANCIERA'!B14 -> 472224220 | C17: ='ESTRUCTURA FINANCIERA'!D14 -> 233832409 | D17: ='ESTRUCTURA FINANCIERA'!F14 -> 128742576 | E17: =IF(C17=0," ",((B17-C17)/C17)) -> 1.0194986
A18: PREPAGADOS | B18: ='ESTRUCTURA FINANCIERA'!B16 -> 0 | C18: ='ESTRUCTURA FINANCIERA'!D16 -> 0 | D18: ='ESTRUCTURA FINANCIERA'!F16 -> 0 | E18: =IF(C18=0," ",((B18-C18)/C18))
A19: .- PASIVO CIRCULANTE NO FINANCIERO | B19: =SUM(B20:B25) -> 11275067827 | C19: =SUM(C20:C25) -> 6862777984 | D19: =SUM(D20:D25) -> 9873890872 | E19: =IF(C19=0," ",((B19-C19)/C19)) -> 0.64293058
A20: CUENTAS PROVEEDORES | B20: ='ESTRUCTURA FINANCIERA'!B33 -> 11275067827 | C20: ='ESTRUCTURA FINANCIERA'!D33 -> 6862777984 | D20: ='ESTRUCTURA FINANCIERA'!F33 -> 9873890872 | E20: =IF(C20=0," ",((B20-C20)/C20)) -> 0.64293058
A21: CUENTAS A PAGAR AL GRUPO C.P. | B21: ='ESTRUCTURA FINANCIERA'!B34 -> 0 | C21: ='ESTRUCTURA FINANCIERA'!D34 -> 0 | D21: ='ESTRUCTURA FINANCIERA'!F34 -> 0 | E21: =IF(C21=0," ",((B21-C21)/C21))
A22: ANTICIPOS DE CLIENTES | B22: ='ESTRUCTURA FINANCIERA'!B35 -> 0 | C22: ='ESTRUCTURA FINANCIERA'!D35 -> 0 | D22: ='ESTRUCTURA FINANCIERA'!F35 -> 0 | E22: =IF(C22=0," ",((B22-C22)/C22))
A23: ADMINISTRACION PUBLICA A C.P. | B23: ='ESTRUCTURA FINANCIERA'!B36 -> 0 | C23: ='ESTRUCTURA FINANCIERA'!D36 -> 0 | D23: ='ESTRUCTURA FINANCIERA'!F36 -> 0 | E23: =IF(C23=0," ",((B23-C23)/C23))
A24: CREDITOS DIFERIDOS | B24: ='ESTRUCTURA FINANCIERA'!B37 -> 0 | C24: ='ESTRUCTURA FINANCIERA'!D37 -> 0 | D24: ='ESTRUCTURA FINANCIERA'!F37 -> 0 | E24: =IF(C24=0," ",((B24-C24)/C24))
A25: OTROS PASIVOS CORRIENTES | B25: ='ESTRUCTURA FINANCIERA'!B38 -> 0 | C25: ='ESTRUCTURA FINANCIERA'!D38 -> 0 | D25: ='ESTRUCTURA FINANCIERA'!F38 -> 0 | E25: =IF(C25=0," ",((B25-C25)/C25))
A27: = INVERSION EN CIRCULANTE | B27: =B12-B30 -> 28185348827 | C27: =C12-C30 -> 24277304266 | D27: =D12-D30 -> 17154026830 | E27: =IF(C27=0," ",((B27-C27)/C27)) -> 0.16097523
A28: % SOBRE VENTAS | B28: =IF('ESTRUCTURA ECONOMICA'!B10=0," ",(B27/'ESTRUCTURA ECONOMICA'!B10)) -> 3.8626149 | C28: =IF('ESTRUCTURA ECONOMICA'!E10=0," ",(C27/'ESTRUCTURA ECONOMICA'!E10)) -> 4.008862 | D28: =IF('ESTRUCTURA ECONOMICA'!G10=0," ",(D27/'ESTRUCTURA ECONOMICA'!G10)) -> 3.936543
A30: TESORERIA NETA | B30: =B31+B32-B33-B34 -> -20892591494 | C30: =C31+C32-C33-C34 -> -18426718835 | D30: =D31+D32-D33-D34 -> -13274395109 | E30: =IF(C30=0," ",((B30-C30)/C30)) -> 0.1338205
A31: EFECTIVO EN CAJA Y BANCOS | B31: ='ESTRUCTURA FINANCIERA'!B10 -> 15121187075 | C31: ='ESTRUCTURA FINANCIERA'!D10 -> 12350077221 | D31: ='ESTRUCTURA FINANCIERA'!F10 -> 14608256735 | E31: =IF(C31=0," ",((B31-C31)/C31)) -> 0.22437996
A32: .+ INVERSIONES FINANCIERAS TEMPORALES | B32: ='ESTRUCTURA FINANCIERA'!B11 -> 13694398052 | C32: ='ESTRUCTURA FINANCIERA'!D11 -> 11492210312 | D32: ='ESTRUCTURA FINANCIERA'!F11 -> 8777835122 | E32: =IF(C32=0," ",((B32-C32)/C32)) -> 0.19162439
A33: .- BANCOS A CORTO PLAZO | B33: ='ESTRUCTURA FINANCIERA'!B31 -> 38558604541 | C33: ='ESTRUCTURA FINANCIERA'!D31 -> 32056991117 | D33: ='ESTRUCTURA FINANCIERA'!F31 -> 27982022945 | E33: =IF(C33=0," ",((B33-C33)/C33)) -> 0.20281421
A34: .- OTRAS DEUDAS FINANCIERAS A CORTO PLAZO | B34: ='ESTRUCTURA FINANCIERA'!B32 -> 11149572080 | C34: ='ESTRUCTURA FINANCIERA'!D32 -> 10212015251 | D34: ='ESTRUCTURA FINANCIERA'!F32 -> 8678464021 | E34: =IF(C34=0," ",((B34-C34)/C34)) -> 0.091809188
A35: CAPITAL DE TRABAJO = RECURSOS PERM. - INMOVILIZADO NETO = INVERSION EN CIRCULANTE +/- TESORERIA NETA

Sheet ANALISIS SOLVENCIA Y MONETARIO
A1: Análisis Financiero de Corto y Largo Plazo
A3: ANALISIS DE LA ESTRUCTURA FINANCIERA
A4: =+'CAPITAL DE TRABAJO'!A4 -> (Expresado en pesos Dominicanos DOP)
A5: ANALISIS DE LA SOLVENCIA
A6: CONCEPTOS | B6: ='ESTRUCTURA ECONOMICA'!B8 -> 45657 | D6: ='ESTRUCTURA ECONOMICA'!E8 -> 45291 | F6: ='ESTRUCTURA ECONOMICA'!G8 -> 44926
A7: ENDEUDAMIENTO FINANCIERO AJUST. (P.FIN./PATRIMONIO) | B7: =('ESTRUCTURA FINANCIERA'!B43+'ESTRUCTURA FINANCIERA'!B44+'ESTRUCTURA FINANCIERA'!B31+'ESTRUCTURA FINANCIERA'!B32)/'ESTRUCTURA FINANCIERA'!B56 -> 10.57868 | D7: =('ESTRUCTURA FINANCIERA'!D43+'ESTRUCTURA FINANCIERA'!D44+'ESTRUCTURA FINANCIERA'!D31+'ESTRUCTURA FINANCIERA'!D32)/'ESTRUCTURA FINANCIERA'!D56 -> 10.343061 | F7: =('ESTRUCTURA FINANCIERA'!F48+'ESTRUCTURA FINANCIERA'!F31+'ESTRUCTURA FINANCIERA'!F32)/'ESTRUCTURA FINANCIERA'!F56 -> 13.282769
A8: ENDEUDAMIENTO FINANCIERO HIST.(P.FIN./PATRIM.. SIN INFL.) | B8: =('ESTRUCTURA FINANCIERA'!B43+'ESTRUCTURA FINANCIERA'!B44+'ESTRUCTURA FINANCIERA'!B31+'ESTRUCTURA FINANCIERA'!B32)/('ESTRUCTURA FINANCIERA'!B56-'ESTRUCTURA FINANCIERA'!B55) -> 10.57868 | D8: =('ESTRUCTURA FINANCIERA'!D43+'ESTRUCTURA FINANCIERA'!D44+'ESTRUCTURA FINANCIERA'!D31+'ESTRUCTURA FINANCIERA'!D32)/('ESTRUCTURA FINANCIERA'!D56-'ESTRUCTURA FINANCIERA'!D55) -> 10.343061 | F8: =('ESTRUCTURA FINANCIERA'!F48+'ESTRUCTURA FINANCIERA'!F31+'ESTRUCTURA FINANCIERA'!F32)/('ESTRUCTURA FINANCIERA'!F56-'ESTRUCTURA FINANCIERA'!F55) -> 13.282769
A9: COBERTURA DE ACTIVOS (REC. PERM./(INV. CIR.+INM.N)) | B9: ='CAPITAL DE TRABAJO'!B10/('ESTRUCTURA FINANCIERA'!B29+'CAPITAL DE TRABAJO'!B27) -> 0.28490835 | D9: ='CAPITAL DE TRABAJO'!C10/('ESTRUCTURA FINANCIERA'!D29+'CAPITAL DE TRABAJO'!C27) -> 0.27072332 | F9: ='CAPITAL DE TRABAJO'!D10/('ESTRUCTURA FINANCIERA'!F29+'CAPITAL DE TRABAJO'!D27) -> 0.26296904
A11: ANALISIS MONETARIO
A12: CONCEPTOS (como % del activo total) | B12: =B6 -> 45657 | D12: =D6 -> 45291 | F12: =F6 -> 44926
A13: . +ACTIVOS MONETARIOS | B13: =+'ESTRUCTURA FINANCIERA'!B30 -> 69307315746 | C13: =(B13/'ESTRUCTURA FINANCIERA'!B$30) -> 1 | D13: =+'ESTRUCTURA FINANCIERA'!D30 -> 55972182010 | E13: =(D13/'ESTRUCTURA FINANCIERA'!D$30) -> 1 | F13: =+'ESTRUCTURA FINANCIERA'!F30 -> 51270616957 | G13: =(F13/'ESTRUCTURA FINANCIERA'!F$30) -> 1
A14: . - PASIVOS MONETARIOS | B14: ='ESTRUCTURA FINANCIERA'!B49 -> 64608414162 | C14: =(B14/'ESTRUCTURA FINANCIERA'!B30) -> 0.93220194 | D14: ='ESTRUCTURA FINANCIERA'!D49 -> 51885480243 | E14: =(D14/'ESTRUCTURA FINANCIERA'!D30) -> 0.92698691 | F14: ='ESTRUCTURA FINANCIERA'!F49 -> 48372248602 | G14: =(F14/'ESTRUCTURA FINANCIERA'!F30) -> 0.94346921
A15: .=POSICION MONETARIA NETA | B15: =B13-B14 -> 4698901584 | C15: =C13-C14 -> 0.06779806 | D15: =D13-D14 -> 4086701767 | E15: =E13-E14 -> 0.073013087 | F15: =F13-F14 -> 2898368355 | G15: =G13-G14 -> 0.056530788
A16: EVALUACIÓN | B16: =IF(B15<0,"GANANCIA POSICION MONETARIA","PERDIDA POSICION MONETARIA") -> PERDIDA POSICION MONETARIA | D16: =IF(D15<0,"GANANCIA POSICION MONETARIA","PERDIDA POSICION MONETARIA") -> PERDIDA POSICION MONETARIA | F16: =IF(F15<0,"GANANCIA POSICION MONETARIA","PERDIDA POSICION MONETARIA") -> PERDIDA POSICION MONETARIA
A17: (- GCIA. MONET., + PDA. MONET.)
I21: =#REF! -> #REF!

Sheet RENTABILIDAD-BENEFICIOS
A1: Evaluación de Rentabilidad
A3: RENTABILIDAD-BENEFICIOS
A4: =+'ANALISIS SOLVENCIA Y MONETARIO'!A4 -> (Expresado en pesos Dominicanos DOP)
A5: RENTABILIDAD-BENEFICIOS
A7: CONCEPTOS | B7: ='ANALISIS SOLVENCIA Y MONETARIO'!B6 -> 45657 | D7: ='ANALISIS SOLVENCIA Y MONETARIO'!D6 -> 45291 | F7: ='CAPITAL DE TRABAJO'!D6 -> 44926
A8: RENTABILIDAD FINANCIERA (AJUST) (B.A.I./PATRIMONIO PROMEDIO.) | B8: =IF(L16=0,I15,I16) -> 0.1553788 | D8: =IF(P16=0,M15,M16) -> 0.19383684 | F8: =IF(T16=0,Q15,Q16) -> 0.18404697
A9: RENTABILIDAD FINANCIERA (HIST.) (B.A.I./PATRIMONIO PROM. SIN INFL.) | B9: =IF(L18=0,I17,I18) -> 0.1553788 | D9: =IF(P18=0,M17,M18) -> 0.19383684 | F9: =IF(T18=0,Q17,Q18) -> 0.18404697
A11: ESTRUCTURA DE BENEFICIOS ANTES DE IMPUESTOS | B11: =B20 -> 45657 | D11: =D20 -> 45291 | F11: =F20 -> 44926
A12: BENEFICIOS ANTES DE IMPUESTOS | B12: =B21 -> 682548271 | C12: =SUM(C13:C16) -> 1 | D12: =D21 -> 676981945 | E12: =SUM(E13:E16) -> 1 | F12: =F21 -> 533435923 | G12: =SUM(G13:G16) -> 1
A13: RESULTADO MONETARIO | B13: ='ESTRUCTURA ECONOMICA'!B25 -> 0 | C13: =(B13/'ESTRUCTURA ECONOMICA'!B29) -> 0 | D13: ='ESTRUCTURA ECONOMICA'!E25 -> 0 | E13: =(D13/'ESTRUCTURA ECONOMICA'!E29) -> 0 | F13: ='ESTRUCTURA ECONOMICA'!G25 -> 0 | G13: =(F13/'ESTRUCTURA ECONOMICA'!G29) -> 0
A14: RESULTADO EN MONEDA EXTRANJERA | B14: ='ESTRUCTURA ECONOMICA'!B24 -> 0 | C14: =(B14/'ESTRUCTURA ECONOMICA'!B29) -> 0 | D14: ='ESTRUCTURA ECONOMICA'!E24 -> 0 | E14: =(D14/'ESTRUCTURA ECONOMICA'!E29) -> 0 | F14: ='ESTRUCTURA ECONOMICA'!G24 -> 0 | G14: =(F14/'ESTRUCTURA ECONOMICA'!G29) -> 0
A15: RESULTADO EXTRAORDINARIO | B15: ='ESTRUCTURA ECONOMICA'!B28 -> 0 | C15: =(B15/'ESTRUCTURA ECONOMICA'!B29) -> 0 | D15: ='ESTRUCTURA ECONOMICA'!E28 -> 0 | E15: =(D15/'ESTRUCTURA ECONOMICA'!E29) -> 0 | F15: ='ESTRUCTURA ECONOMICA'!G28 -> 0 | G15: =(F15/'ESTRUCTURA ECONOMICA'!G29) -> 0 | I15: =IF('ESTRUCTURA ECONOMICA'!$E$29=0,('ESTRUCTURA ECONOMICA'!$B$29/'ESTRUCTURA FINANCIERA'!$B$56),('ESTRUCTURA ECONOMICA'!$B$29/(('ESTRUCTURA FINANCIERA'!$B$56+'ESTRUCTURA FINANCIERA'!$D$56)/2))) -> 0.1553788 | J15: ='ESTRUCTURA ECONOMICA'!$B$27 -> 682548271 | K15: =IF(J15=0,1,(J15/ABS(J15))) -> 1 | M15: =IF('ESTRUCTURA ECONOMICA'!$G$29=0,('ESTRUCTURA ECONOMICA'!$E$29/'ESTRUCTURA FINANCIERA'!$D$56),('ESTRUCTURA ECONOMICA'!$E$29/(('ESTRUCTURA FINANCIERA'!$D$56+'ESTRUCTURA FINANCIERA'!$F$56)/2))) -> 0.19383684 | N15: ='ESTRUCTURA ECONOMICA'!$E$27 -> 676981945 | O15: =IF(N15=0,1,(N15/ABS(N15))) -> 1 | Q15: =IF('ESTRUCTURA ECONOMICA'!$G$29=0,0,('ESTRUCTURA ECONOMICA'!$G$29/'ESTRUCTURA FINANCIERA'!$F$56)) -> 0.18404697 | R15: ='ESTRUCTURA ECONOMICA'!$G$27 -> 533435923 | S15: =IF(R15=0,1,(R15/ABS(R15))) -> 1 | U15: Resultado de actividades ordinarias
A16: RESULTADO TIPICO | B16: =B22+B23 -> 682548271 | C16: =(B16/'ESTRUCTURA ECONOMICA'!B29) -> 1 | D16: =D22+D23 -> 676981945 | E16: =(D16/'ESTRUCTURA ECONOMICA'!E29) -> 1 | F16: =F22+F23 -> 533435923 | G16: =(F16/'ESTRUCTURA ECONOMICA'!G29) -> 1 | I16: =IF('ESTRUCTURA ECONOMICA'!$E$29=0,('ESTRUCTURA ECONOMICA'!$B$29/ABS('ESTRUCTURA FINANCIERA'!$B$56)),('ESTRUCTURA ECONOMICA'!$B$29/ABS((('ESTRUCTURA FINANCIERA'!$B$56+'ESTRUCTURA FINANCIERA'!$D$56)/2)))) -> 0.1553788 | J16: =('ESTRUCTURA FINANCIERA'!$B$56+'ESTRUCTURA FINANCIERA'!$D$56)/2 -> 4.3928017e+09 | K16: =IF(J16=0,1,(J16/ABS(J16))) -> 1 | L16: =K15+K16 -> 2 | M16: =IF('ESTRUCTURA ECONOMICA'!$G$29=0,('ESTRUCTURA ECONOMICA'!$E$29/ABS('ESTRUCTURA FINANCIERA'!$D$56)),('ESTRUCTURA ECONOMICA'!$E$29/ABS((('ESTRUCTURA FINANCIERA'!$D$56+'ESTRUCTURA FINANCIERA'!$F$56)/2)))) -> 0.19383684 | N16: =('ESTRUCTURA FINANCIERA'!$D$56+'ESTRUCTURA FINANCIERA'!$F$56)/2 -> 3492535061 | O16: =IF(N16=0,1,(N16/ABS(N16))) -> 1 | P16: =O15+O16 -> 2 | Q16: =IF('ESTRUCTURA ECONOMICA'!$G$29=0,0,('ESTRUCTURA ECONOMICA'!$G$29/ABS('ESTRUCTURA FINANCIERA'!$F$56))) -> 0.18404697 | R16: ='ESTRUCTURA FINANCIERA'!$F$56 -> 2898368355 | S16: =IF(R16=0,1,(R16/ABS(R16))) -> 1 | T16: =S15+S16 -> 2 | U16: Patrimonio promedio dos años
I17: =IF('ESTRUCTURA ECONOMICA'!$E$29=0,('ESTRUCTURA ECONOMICA'!$B$29/('ESTRUCTURA FINANCIERA'!$B$56-'ESTRUCTURA FINANCIERA'!$B$55)),('ESTRUCTURA ECONOMICA'!$B$29/((('ESTRUCTURA FINANCIERA'!$B$56-'ESTRUCTURA FINANCIERA'!$B$55)+('ESTRUCTURA FINANCIERA'!$D$56-'ESTRUCTURA FINANCIERA'!$D$55))/2))) -> 0.1553788 | J17: ='ESTRUCTURA ECONOMICA'!$B$29 -> 682548271 | K17: =IF(J17=0,1,(J17/ABS(J17))) -> 1 | M17: =IF('ESTRUCTURA ECONOMICA'!$G$29=0,('ESTRUCTURA ECONOMICA'!$E$29/('ESTRUCTURA FINANCIERA'!$D$56-'ESTRUCTURA FINANCIERA'!$D$55)),('ESTRUCTURA ECONOMICA'!$E$29/((('ESTRUCTURA FINANCIERA'!$D$56-'ESTRUCTURA FINANCIERA'!$D$55)+('ESTRUCTURA FINANCIERA'!$F$56-'ESTRUCTURA FINANCIERA'!$F$55))/2))) -> 0.19383684 | N17: ='ESTRUCTURA ECONOMICA'!$G$29 -> 533435923 | O17: =IF(N17=0,1,(N17/ABS(N17))) -> 1 | Q17: =IF('ESTRUCTURA ECONOMICA'!$G$29=0,0,('ESTRUCTURA ECONOMICA'!$G$29/('ESTRUCTURA FINANCIERA'!$F$56-'ESTRUCTURA FINANCIERA'!$F$55))) -> 0.18404697 | R17: ='ESTRUCTURA ECONOMICA'!$G$27 -> 533435923 | S17: =IF(R17=0,1,(R17/ABS(R17))) -> 1 | U17: Beneficios antes de impuestos
A18: RENTABILIDAD ECONOMICA (B.A.I./VENTAS) | B18: ='ESTRUCTURA ECONOMICA'!B29/'ESTRUCTURA ECONOMICA'!B10 -> 0.093538709 | D18: ='ESTRUCTURA ECONOMICA'!E29/'ESTRUCTURA ECONOMICA'!E10 -> 0.11178865 | F18: ='ESTRUCTURA ECONOMICA'!G29/'ESTRUCTURA ECONOMICA'!G10 -> 0.12241402 | I18: =IF('ESTRUCTURA ECONOMICA'!$E$29=0,('ESTRUCTURA ECONOMICA'!$B$29/ABS('ESTRUCTURA FINANCIERA'!$B$56-'ESTRUCTURA FINANCIERA'!$B$55)),('ESTRUCTURA ECONOMICA'!$B$29/ABS((('ESTRUCTURA FINANCIERA'!$B$56-'ESTRUCTURA FINANCIERA'!$B$55)+('ESTRUCTURA FINANCIERA'!$D$56-'ESTRUCTURA FINANCIERA'!$D$55))/2))) -> 0.1553788 | J18: =(('ESTRUCTURA FINANCIERA'!B56-'ESTRUCTURA FINANCIERA'!B55)+('ESTRUCTURA FINANCIERA'!D56-'ESTRUCTURA FINANCIERA'!D55))/2 -> 4.3928017e+09 | K18: =IF(J18=0,1,(J18/ABS(J18))) -> 1 | L18: =K17+K18 -> 2 | M18: =IF('ESTRUCTURA ECONOMICA'!$G$29=0,('ESTRUCTURA ECONOMICA'!$E$29/ABS('ESTRUCTURA FINANCIERA'!$D$56-'ESTRUCTURA FINANCIERA'!$D$55)),('ESTRUCTURA ECONOMICA'!$E$29/ABS((('ESTRUCTURA FINANCIERA'!$D$56-'ESTRUCTURA FINANCIERA'!$D$55)+('ESTRUCTURA FINANCIERA'!$F$56-'ESTRUCTURA FINANCIERA'!$F$55))/2))) -> 0.19383684 | N18: =(('ESTRUCTURA FINANCIERA'!$D$56-'ESTRUCTURA FINANCIERA'!$D$55)+('ESTRUCTURA FINANCIERA'!$F$56-'ESTRUCTURA FINANCIERA'!$F$55))/2 -> 3492535061 | O18: =IF(N18=0,1,(N18/ABS(N18))) -> 1 | P18: =O17+O18 -> 2 | Q18: =IF('ESTRUCTURA ECONOMICA'!$G$29=0,0,('ESTRUCTURA ECONOMICA'!$G$29/('ESTRUCTURA FINANCIERA'!$F$56-'ESTRUCTURA FINANCIERA'!$F$55))) -> 0.18404697 | R18: =('ESTRUCTURA FINANCIERA'!$F$56-'ESTRUCTURA FINANCIERA'!$F$55) -> 2898368355 | S18: =IF(R18=0,1,(R18/ABS(R18))) -> 1 | T18: =S17+S18 -> 2 | U18: Patrimonio - sup por revalor
A20: BENEFICIOS/VENTAS TOTALES | B20: =B7 -> 45657 | D20: =D7 -> 45291 | F20: =F7 -> 44926
A21: BENEFICIOS ANTES DE IMPUESTOS | B21: =B22+B23+B24+B25+B26 -> 682548271 | C21: =C22+C23+C24+C25+C26 -> 0.093538709 | D21: =D22+D23+D24+D25+D26 -> 676981945 | E21: =E22+E23+E24+E25+E26 -> 0.11178865 | F21: =F22+F23+F24+F25+F26 -> 533435923 | G21: =(F21/'ESTRUCTURA ECONOMICA'!G10) -> 0.12241402
A22: UTILIDAD NETA EN OPERACIONES | B22: ='ESTRUCTURA ECONOMICA'!B21 -> -2117776331 | C22: =(B22/'ESTRUCTURA ECONOMICA'!B10) -> -0.29022718 | D22: ='ESTRUCTURA ECONOMICA'!E21 -> -1486428814 | E22: =(D22/'ESTRUCTURA ECONOMICA'!E10) -> -0.24545097 | F22: ='ESTRUCTURA ECONOMICA'!G21 -> -1264999965 | G22: =(F22/'ESTRUCTURA ECONOMICA'!G10) -> -0.29029491
A23: RESULTADO FINANCIERO (INGRESOS-EGRESOS) | B23: ='ESTRUCTURA ECONOMICA'!B22-'ESTRUCTURA ECONOMICA'!B23 -> 2800324602 | C23: =(B23/'ESTRUCTURA ECONOMICA'!B10) -> 0.38376589 | D23: ='ESTRUCTURA ECONOMICA'!E22-'ESTRUCTURA ECONOMICA'!E23 -> 2163410759 | E23: =(D23/'ESTRUCTURA ECONOMICA'!E10) -> 0.35723963 | F23: ='ESTRUCTURA ECONOMICA'!G22-'ESTRUCTURA ECONOMICA'!G23 -> 1798435888 | G23: =(F23/'ESTRUCTURA ECONOMICA'!G10) -> 0.41270894
A24: RESULTADO MONETARIO | B24: =B13 -> 0 | C24: =(B24/'ESTRUCTURA ECONOMICA'!B10) -> 0 | D24: =D13 -> 0 | E24: =(D24/'ESTRUCTURA ECONOMICA'!E10) -> 0 | F24: =F13 -> 0 | G24: =(F24/'ESTRUCTURA ECONOMICA'!G10) -> 0
A25: RESULTADO EN MONEDA EXTRANJERA | B25: ='ESTRUCTURA ECONOMICA'!B24 -> 0 | C25: =(B25/'ESTRUCTURA ECONOMICA'!B10) -> 0 | D25: ='ESTRUCTURA ECONOMICA'!E24 -> 0 | E25: =(D25/'ESTRUCTURA ECONOMICA'!E10) -> 0 | F25: ='ESTRUCTURA ECONOMICA'!G24 -> 0 | G25: =(F25/'ESTRUCTURA ECONOMICA'!G10) -> 0
A26: RESULTADO EXTRAORDINARIO | B26: ='ESTRUCTURA ECONOMICA'!B28 -> 0 | C26: =(B26/'ESTRUCTURA ECONOMICA'!B10) -> 0 | D26: ='ESTRUCTURA ECONOMICA'!E28 -> 0 | E26: =(D26/'ESTRUCTURA ECONOMICA'!E10) -> 0 | F26: ='ESTRUCTURA ECONOMICA'!G28 -> 0 | G26: =(F26/'ESTRUCTURA ECONOMICA'!G10) -> 0

Sheet GENERACION DE RECURSOS
A1: Capacidad de Pago
A3: GENERACION DE RECURSOS
A4: =+'RENTABILIDAD-BENEFICIOS'!A4 -> (Expresado en pesos Dominicanos DOP)
A6: CONCEPTOS | B6: ='RENTABILIDAD-BENEFICIOS'!B7 -> 45657 | D6: ='RENTABILIDAD-BENEFICIOS'!D7 -> 45291 | F6: ='RENTABILIDAD-BENEFICIOS'!F7 -> 44926
A7: RECURSOS GENERADOS: | B7: =IF(B6=0," ",B8+B9+B10-B11+B12) -> 1651641199 | D7: =IF(D6=0," ",D8+D9+D10-D11+D12) -> 1285366108 | F7: =IF(F6=0," ",F8+F9+F10-F11+F12) -> 922082241
A8: BENEFICIO NETO | B8: =IF(B6=0," ",'ESTRUCTURA ECONOMICA'!B31) -> 623074145 | D8: =IF(D6=0," ",'ESTRUCTURA ECONOMICA'!E31) -> 638333412 | F8: =IF(F6=0," ",'ESTRUCTURA ECONOMICA'!G31) -> 524467786
A9: + AMORTIZACIONES (DEP.) | B9: =IF(B6=0," ",'ESTRUCTURA ECONOMICA'!B18) -> 0 | D9: =IF(D6=0," ",'ESTRUCTURA ECONOMICA'!E18) -> 0 | F9: =IF(F6=0," ",'ESTRUCTURA ECONOMICA'!G18) -> 0
A10: + PROVISIONES | B10: =IF(B6=0," ",'ESTRUCTURA ECONOMICA'!B19) -> 1028567054 | D10: =IF(D6=0," ",'ESTRUCTURA ECONOMICA'!E19) -> 647032696 | F10: =IF(F6=0," ",'ESTRUCTURA ECONOMICA'!G19) -> 397614455
A11: +/- RESULTADOS EXTRAORDINARIOS | B11: =IF(B6=0," ",'ESTRUCTURA ECONOMICA'!B28) -> 0 | D11: =IF(D6=0," ",'ESTRUCTURA ECONOMICA'!E28) -> 0 | F11: =IF(F6=0," ",'ESTRUCTURA ECONOMICA'!G28) -> 0
A12: - DIVIDENDOS | B12: =IF(B6=0," ",'ESTRUCTURA ECONOMICA'!B32) -> 0 | D12: =IF(D6=0," ",'ESTRUCTURA ECONOMICA'!E32) -> 0 | F12: =IF(F6=0," ",'ESTRUCTURA ECONOMICA'!G32) -> 0
I13: FALSE
A14: COMPOSICION DE LOS RECURSOS AUTOGENERADOS | B14: =B6 -> 45657 | C14: % | D14: =D6 -> 45291 | E14: % | F14: =F6 -> 44926 | G14: %
A15: RESULTADO MONETARIO | B15: =IF(B6=0," ",'ESTRUCTURA ECONOMICA'!B25) -> 0 | C15: =IF(B6=0," ",B15/B7) -> 0 | D15: =IF(D6=0," ",'ESTRUCTURA ECONOMICA'!E25) -> 0 | E15: =IF(D6=0," ",D15/D7) -> 0 | F15: =IF(F6=0," ",'ESTRUCTURA ECONOMICA'!G25) -> 0 | G15: =IF(F6=0," ",F15/F7) -> 0
A16: RESULTADO EN MONEDA EXTRAJERA | B16: =IF(B6=0," ",'ESTRUCTURA ECONOMICA'!B24) -> 0 | C16: =IF(B6=0," ",B16/B7) -> 0 | D16: =IF(D6=0," ",'ESTRUCTURA ECONOMICA'!E24) -> 0 | E16: =IF(D6=0," ",D16/D7) -> 0 | F16: =IF(F6=0," ",'ESTRUCTURA ECONOMICA'!G24) -> 0 | G16: =IF(F6=0," ",F16/F7) -> 0 | AP16: =IF('ESTRUCTURA FINANCIERA'!D22=0,#REF!,('ESTRUCTURA FINANCIERA'!B22-'ESTRUCTURA FINANCIERA'!D22)) -> #REF! | AQ16: =IF(#REF!=0,AP16,#REF!) -> #REF! | AR16: =IF(AP16=0,'ESTRUCTURA ECONOMICA'!B18,AQ16) -> #REF!
A17: RECURSOS GENERADOS TIPICOS | B17: =IF(B6=0," ",B7-B15-B16) -> 1651641199 | C17: =IF(B6=0," ",B17/B7) -> 1 | D17: =IF(D6=0," ",D7-D15-D16) -> 1285366108 | E17: =IF(D6=0," ",D17/D7) -> 1 | F17: =IF(F6=0," ",F7-F15-F16) -> 922082241 | G17: =IF(F6=0," ",F17/F7) -> 1
A18: TOTAL | B18: =SUM(B15:B17) -> 1651641199 | C18: =SUM(C15:C17) -> 1 | D18: =SUM(D15:D17) -> 1285366108 | E18: =SUM(E15:E17) -> 1 | F18: =SUM(F15:F17) -> 922082241 | G18: =SUM(G15:G17) -> 1
A20: COBERTURA DE EGRESOS FINANCIEROS | B20: ='RENTABILIDAD-BENEFICIOS'!B7 -> 45657 | D20: ='RENTABILIDAD-BENEFICIOS'!D7 -> 45291 | F20: ='RENTABILIDAD-BENEFICIOS'!F7 -> 44926
A21: EBITDA | B21: =IF(B6=0," ",'ESTRUCTURA ECONOMICA'!B21+'ESTRUCTURA ECONOMICA'!B18) -> -2117776331 | D21: =IF(D6=0," ",'ESTRUCTURA ECONOMICA'!E21+'ESTRUCTURA ECONOMICA'!E18) -> -1486428814 | F21: =IF(F6=0," ",'ESTRUCTURA ECONOMICA'!G21+'ESTRUCTURA ECONOMICA'!G18) -> -1264999965 | AP21: =IF('ESTRUCTURA FINANCIERA'!F22=0,#REF!,('ESTRUCTURA FINANCIERA'!D22-'ESTRUCTURA FINANCIERA'!F23)) -> #REF! | AQ21: =IF(#REF!=0,AP21,#REF!) -> #REF! | AR21: =IF(AP21=0,'ESTRUCTURA ECONOMICA'!E18,AQ21) -> #REF!
A22: EBITDA/EGRESOS FINANCIEROS | B22: =IF(B6=0," ",(('ESTRUCTURA ECONOMICA'!B21+'ESTRUCTURA ECONOMICA'!B18)/'ESTRUCTURA ECONOMICA'!B23)) -> #DIV/0! | D22: =IF(D6=0," ",(('ESTRUCTURA ECONOMICA'!E21+'ESTRUCTURA ECONOMICA'!E18)/'ESTRUCTURA ECONOMICA'!E23)) -> #DIV/0! | F22: =IF(F6=0," ",(('ESTRUCTURA ECONOMICA'!G21+'ESTRUCTURA ECONOMICA'!G18)/'ESTRUCTURA ECONOMICA'!G23)) -> #DIV/0!
A24: CAPACIDAD DE PAGO DEUDA | B24: =B6 -> 45657 | D24: =D6 -> 45291 | F24: =F6 -> 44926
A25: PASIVO A L.P./RECURSOS GENERADOS | B25: =IF(B6=0," ",'ESTRUCTURA FINANCIERA'!B48/'GENERACION DE RECURSOS'!B7) -> 2.1948894 | D25: =IF(D6=0," ",'ESTRUCTURA FINANCIERA'!D48/'GENERACION DE RECURSOS'!D7) -> 2.1423436 | F25: =IF(F6=0," ",'ESTRUCTURA FINANCIERA'!F48/'GENERACION DE RECURSOS'!F7) -> 1.9931745
A26: DEUDA FINANCIERA TOTAL/RECURSOS GENERADOS | B26: =IF(B6=0," ",('ESTRUCTURA FINANCIERA'!B31+'ESTRUCTURA FINANCIERA'!B32+'ESTRUCTURA FINANCIERA'!B43+'ESTRUCTURA FINANCIERA'!B44)/('GENERACION DE RECURSOS'!B7)) -> 30.096232 | D26: =IF(D6=0," ",('ESTRUCTURA FINANCIERA'!D31+'ESTRUCTURA FINANCIERA'!D32+'ESTRUCTURA FINANCIERA'!D43+'ESTRUCTURA FINANCIERA'!D44)/('GENERACION DE RECURSOS'!D7)) -> 32.884799 | F26: =IF(F6=0," ",('ESTRUCTURA FINANCIERA'!F31+'ESTRUCTURA FINANCIERA'!F32+'ESTRUCTURA FINANCIERA'!F43+'ESTRUCTURA FINANCIERA'!F44)/('GENERACION DE RECURSOS'!F7)) -> 39.75837
A27: PASIVO A L.P./RECURSOS GENERADOS TIPICOS | B27: =IF(B6=0," ",'ESTRUCTURA FINANCIERA'!B48/'GENERACION DE RECURSOS'!B17) -> 2.1948894 | D27: =IF(D6=0," ",'ESTRUCTURA FINANCIERA'!D48/'GENERACION DE RECURSOS'!D17) -> 2.1423436 | F27: =IF(F6=0," ",'ESTRUCTURA FINANCIERA'!F48/'GENERACION DE RECURSOS'!F17) -> 1.9931745
A28: DEUDA FINANCIERA TOTAL/RECURSOS GENERADOS TIPICOS | B28: =IF(B6=0," ",('ESTRUCTURA FINANCIERA'!B43+'ESTRUCTURA FINANCIERA'!B44+'ESTRUCTURA FINANCIERA'!B31+'ESTRUCTURA FINANCIERA'!B32)/B17) -> 30.096232 | D28: =IF(D6=0," ",('ESTRUCTURA FINANCIERA'!D43+'ESTRUCTURA FINANCIERA'!D44+'ESTRUCTURA FINANCIERA'!D31+'ESTRUCTURA FINANCIERA'!D32)/D17) -> 32.884799 | F28: =IF(F6=0," ",('ESTRUCTURA FINANCIERA'!F43+'ESTRUCTURA FINANCIERA'!F44+'ESTRUCTURA FINANCIERA'!F31+'ESTRUCTURA FINANCIERA'!F32)/F17) -> 39.75837
A30: Donde: Deuda Financiera Total = Bancos a L.P.+ Otras Deudas Financieras a L.P. + Bancos C.P. + Otras Deudas Financieras a C.P.
A31: Editda: Utilidad en Operaciones + Depreciación y Amortización

Sheet QUIEBRA
A1: Análisis de Quiebra Técnica
A2: Notación | B2: Índice | C2: Ponderación | D2: ='ESTRUCTURA FINANCIERA'!B9 -> 45657 | E2: ='ESTRUCTURA FINANCIERA'!D9 -> 45291 | F2: ='ESTRUCTURA FINANCIERA'!F9 -> 44926
A3: X1 | B3: Capital de trabajo /Total Activo | C3: 1.2 | D3: =('ESTRUCTURA FINANCIERA'!B17-'ESTRUCTURA FINANCIERA'!B39)/'ESTRUCTURA FINANCIERA'!B30 -> 0.10522349 | E3: =('ESTRUCTURA FINANCIERA'!D17-'ESTRUCTURA FINANCIERA'!D39)/'ESTRUCTURA FINANCIERA'!D30 -> 0.10452666 | F3: =('ESTRUCTURA FINANCIERA'!F17-'ESTRUCTURA FINANCIERA'!F39)/'ESTRUCTURA FINANCIERA'!F30 -> 0.075669691
A4: X2 | B4: Utilidades Retenidas / Total Activo | C4: 1.4 | D4: ='ESTRUCTURA FINANCIERA'!B54/'ESTRUCTURA FINANCIERA'!B30 -> 0.0085405189 | E4: ='ESTRUCTURA FINANCIERA'!D54/'ESTRUCTURA FINANCIERA'!D30 -> 0.010834252 | F4: ='ESTRUCTURA FINANCIERA'!F54/'ESTRUCTURA FINANCIERA'!F30 -> 0.0097179325
A5: X3 | B5: Ut antes ISLR / Total Activo | C5: 3.3 | D5: ='ESTRUCTURA ECONOMICA'!B29/'ESTRUCTURA FINANCIERA'!B30 -> 0.0098481418 | E5: ='ESTRUCTURA ECONOMICA'!E29/'ESTRUCTURA FINANCIERA'!D30 -> 0.012094971 | F5: ='ESTRUCTURA ECONOMICA'!G29/'ESTRUCTURA FINANCIERA'!F30 -> 0.01040432
A6: X4 | B6: Total Patrimonio / Total Pasivo | C6: 0.6 | D6: ='ESTRUCTURA FINANCIERA'!B56/'ESTRUCTURA FINANCIERA'!B49 -> 0.072728942 | E6: ='ESTRUCTURA FINANCIERA'!D56/'ESTRUCTURA FINANCIERA'!D49 -> 0.078763881 | F6: ='ESTRUCTURA FINANCIERA'!F56/'ESTRUCTURA FINANCIERA'!F49 -> 0.059917999
A7: X5 | B7: Ventas netas / Total activos | C7: 1 | D7: ='ESTRUCTURA ECONOMICA'!B10/'ESTRUCTURA FINANCIERA'!B30 -> 0.10528413 | E7: ='ESTRUCTURA ECONOMICA'!E10/'ESTRUCTURA FINANCIERA'!D30 -> 0.10819498 | F7: ='ESTRUCTURA ECONOMICA'!G10/'ESTRUCTURA FINANCIERA'!F30 -> 0.084992879
A8: Riesgo Crediticio (x) | B8: Altman | D8: =SUMPRODUCT(C3:C7,D3:D7) -> 0.31964527 | E8: =SUMPRODUCT(C3:C7,E3:E7) -> 0.33596667 | F8: =SUMPRODUCT(C3:C7,F3:F7) -> 0.25968667
A11: Z1 | B11: Liquidez | C11: 0.4 | D11: ='ESTRUCTURA FINANCIERA'!B17/'ESTRUCTURA FINANCIERA'!B39 -> 1.1195862 | E11: ='ESTRUCTURA FINANCIERA'!D17/'ESTRUCTURA FINANCIERA'!D39 -> 1.1190794 | F11: ='ESTRUCTURA FINANCIERA'!F17/'ESTRUCTURA FINANCIERA'!F39 -> 1.0833713
A12: Z2 | B12: Apalancamiento interno | C12: 0.6 | D12: =INDICES!B17 -> 0.072728942 | E12: =INDICES!D17 -> 0.078763881 | F12: =INDICES!F17 -> 0.059917999
A13: Riesgo Crediticio (z) | B13: Modificado | D13: =SUMPRODUCT(C11:C12,D11:D12) -> 0.49147186 | E13: =SUMPRODUCT(C11:C12,E11:E12) -> 0.4948901 | F13: =SUMPRODUCT(C11:C12,F11:F12) -> 0.46929932
A15: Alman =X1*1,2+X2*1,4+X3*3,3+X4*0,6+X5*1
A16: Z= Z1*0,4+Z2*0,6
A18: Altman
A19: >3 | B19: Solvente
A20: 2,7<=x<=3 | B20: Precaución
A21: 2,7<=x<=1,8 | B21: Alerta
A22: x<1,8 | B22: Técnicamente quebrada
A24: Sánchez
A25: z>1,4 | B25: Crédito excelente
A26: 0,66<=z<=1,4 | B26: Riesgo normal
A27: z<0,66 | B27: Crédito riesgoso o malo

Sheet INDICES
A1: Resumen de indicadores financieros
A4: Índice | B4: ='ESTRUCTURA ECONOMICA'!B8 -> 45657 | D4: ='ESTRUCTURA FINANCIERA'!D9 -> 45291 | F4: ='ESTRUCTURA ECONOMICA'!G8 -> 44926 | K4: 0
A5: Capital de trabajo | B5: ='ESTRUCTURA FINANCIERA'!B17-'ESTRUCTURA FINANCIERA'!B39 -> 7292757333 | D5: ='ESTRUCTURA FINANCIERA'!D17-'ESTRUCTURA FINANCIERA'!D39 -> 5850585431 | F5: ='ESTRUCTURA FINANCIERA'!F17-'ESTRUCTURA FINANCIERA'!F39 -> 3879631721 | H5: ='ESTRUCTURA FINANCIERA'!H24-'ESTRUCTURA FINANCIERA'!H47 -> 0 | J5: ='ESTRUCTURA FINANCIERA'!J24-'ESTRUCTURA FINANCIERA'!J47 -> 0 | K5: 0
A7: LIQUIDEZ | B7: =B4 -> 45657 | D7: =D4 -> 45291 | F7: =F4 -> 44926 | H7: =H4 -> 0 | J7: =J4 -> 0 | K7: =K4 -> 0
A8: Indice corriente o circulante | B8: ='ESTRUCTURA FINANCIERA'!B17/'ESTRUCTURA FINANCIERA'!B39 -> 1.1195862 | D8: ='ESTRUCTURA FINANCIERA'!D17/'ESTRUCTURA FINANCIERA'!D39 -> 1.1190794 | F8: ='ESTRUCTURA FINANCIERA'!F17/'ESTRUCTURA FINANCIERA'!F39 -> 1.0833713 | H8: ='ESTRUCTURA FINANCIERA'!H24/'ESTRUCTURA FINANCIERA'!H47 -> #DIV/0! | J8: ='ESTRUCTURA FINANCIERA'!J24/'ESTRUCTURA FINANCIERA'!J47 -> #DIV/0! | K8: #DIV/0!
A9: Prueba ácida | B9: =('ESTRUCTURA FINANCIERA'!B17-'ESTRUCTURA FINANCIERA'!B15)/'ESTRUCTURA FINANCIERA'!B39 -> 1.1192612 | D9: =('ESTRUCTURA FINANCIERA'!D17-'ESTRUCTURA FINANCIERA'!D15)/'ESTRUCTURA FINANCIERA'!D39 -> 1.1175207 | F9: =('ESTRUCTURA FINANCIERA'!F17-'ESTRUCTURA FINANCIERA'!F15)/'ESTRUCTURA FINANCIERA'!F39 -> 1.0809392 | H9: =('ESTRUCTURA FINANCIERA'!H24-'ESTRUCTURA FINANCIERA'!H22)/'ESTRUCTURA FINANCIERA'!H47 -> #DIV/0! | J9: =('ESTRUCTURA FINANCIERA'!J24-'ESTRUCTURA FINANCIERA'!J22)/'ESTRUCTURA FINANCIERA'!J47 -> #DIV/0! | K9: #DIV/0!
A10: Prueba super ácida | B10: =('ESTRUCTURA FINANCIERA'!B10+'ESTRUCTURA FINANCIERA'!B11)/'ESTRUCTURA FINANCIERA'!B39 -> 0.47251643 | D10: =('ESTRUCTURA FINANCIERA'!D10+'ESTRUCTURA FINANCIERA'!D11)/'ESTRUCTURA FINANCIERA'!D39 -> 0.48527217 | F10: =('ESTRUCTURA FINANCIERA'!F10+'ESTRUCTURA FINANCIERA'!F11)/'ESTRUCTURA FINANCIERA'!F39 -> 0.50255516 | H10: =('ESTRUCTURA FINANCIERA'!H17+'ESTRUCTURA FINANCIERA'!H18)/'ESTRUCTURA FINANCIERA'!H47 -> #DIV/0! | J10: =('ESTRUCTURA FINANCIERA'!J17+'ESTRUCTURA FINANCIERA'!J18)/'ESTRUCTURA FINANCIERA'!J47 -> #DIV/0! | K10: #DIV/0!
A11: Razón de Fondo de Maniobra | B11: =B5/'ESTRUCTURA FINANCIERA'!B30 -> 0.10522349 | D11: =D5/'ESTRUCTURA FINANCIERA'!D30 -> 0.10452666 | F11: =F5/'ESTRUCTURA FINANCIERA'!F30 -> 0.075669691 | H11: =H5/'ESTRUCTURA FINANCIERA'!H38 -> #DIV/0! | J11: =J5/'ESTRUCTURA FINANCIERA'!J38 -> #DIV/0! | K11: #DIV/0!
A13: APALANCAMIENTO y CAPITALIZACiÓN | B13: =B4 -> 45657 | D13: =D4 -> 45291 | F13: =F4 -> 44926 | H13: =H4 -> 0 | J13: =J4 -> 0 | K13: =K4 -> 0
A14: Índice de endeudamiento | B14: ='ESTRUCTURA FINANCIERA'!B49/'ESTRUCTURA FINANCIERA'!B30 -> 0.93220194 | D14: ='ESTRUCTURA FINANCIERA'!D49/'ESTRUCTURA FINANCIERA'!D30 -> 0.92698691 | F14: ='ESTRUCTURA FINANCIERA'!F49/'ESTRUCTURA FINANCIERA'!F30 -> 0.94346921 | H14: ='ESTRUCTURA FINANCIERA'!H57/'ESTRUCTURA FINANCIERA'!H38 -> #DIV/0! | J14: ='ESTRUCTURA FINANCIERA'!J57/'ESTRUCTURA FINANCIERA'!J38 -> #DIV/0! | K14: #DIV/0!
A15: Índice de autonomía | B15: ='ESTRUCTURA FINANCIERA'!B56/'ESTRUCTURA FINANCIERA'!B30 -> 0.06779806 | D15: ='ESTRUCTURA FINANCIERA'!D56/'ESTRUCTURA FINANCIERA'!D30 -> 0.073013087 | F15: ='ESTRUCTURA FINANCIERA'!F56/'ESTRUCTURA FINANCIERA'!F30 -> 0.056530788 | H15: ='ESTRUCTURA FINANCIERA'!H64/'ESTRUCTURA FINANCIERA'!H38 -> #DIV/0! | J15: ='ESTRUCTURA FINANCIERA'!J64/'ESTRUCTURA FINANCIERA'!J38 -> #DIV/0! | K15: #DIV/0!
A16: Apalancamiento externo | B16: ='ESTRUCTURA FINANCIERA'!B49/'ESTRUCTURA FINANCIERA'!B56 -> 13.749684 | D16: ='ESTRUCTURA FINANCIERA'!D49/'ESTRUCTURA FINANCIERA'!D56 -> 12.696175 | F16: ='ESTRUCTURA FINANCIERA'!F49/'ESTRUCTURA FINANCIERA'!F56 -> 16.689476 | H16: ='ESTRUCTURA FINANCIERA'!H57/'ESTRUCTURA FINANCIERA'!H64 -> #DIV/0! | J16: ='ESTRUCTURA FINANCIERA'!J57/'ESTRUCTURA FINANCIERA'!J64 -> #DIV/0! | K16: #DIV/0!
A17: Apalancamiento interno | B17: ='ESTRUCTURA FINANCIERA'!B56/'ESTRUCTURA FINANCIERA'!B49 -> 0.072728942 | D17: ='ESTRUCTURA FINANCIERA'!D56/'ESTRUCTURA FINANCIERA'!D49 -> 0.078763881 | F17: ='ESTRUCTURA FINANCIERA'!F56/'ESTRUCTURA FINANCIERA'!F49 -> 0.059917999 | H17: ='ESTRUCTURA FINANCIERA'!H64/'ESTRUCTURA FINANCIERA'!H57 -> #DIV/0! | J17: ='ESTRUCTURA FINANCIERA'!J64/'ESTRUCTURA FINANCIERA'!J57 -> #DIV/0! | K17: #DIV/0!
A18: Capitalizacion externa | B18: ='ESTRUCTURA FINANCIERA'!B48/('ESTRUCTURA FINANCIERA'!B56+'ESTRUCTURA FINANCIERA'!B48) -> 0.4355044 | D18: ='ESTRUCTURA FINANCIERA'!D48/('ESTRUCTURA FINANCIERA'!D56+'ESTRUCTURA FINANCIERA'!D48) -> 0.40256371 | F18: ='ESTRUCTURA FINANCIERA'!F48/('ESTRUCTURA FINANCIERA'!F56+'ESTRUCTURA FINANCIERA'!F48) -> 0.38804434 | H18: ='ESTRUCTURA FINANCIERA'!H56/('ESTRUCTURA FINANCIERA'!H64+'ESTRUCTURA FINANCIERA'!H56) -> #DIV/0! | J18: ='ESTRUCTURA FINANCIERA'!J56/('ESTRUCTURA FINANCIERA'!J64+'ESTRUCTURA FINANCIERA'!J56) -> #DIV/0! | K18: #DIV/0!
A19: Capitalizacion interna | B19: ='ESTRUCTURA FINANCIERA'!B56/('ESTRUCTURA FINANCIERA'!B56+'ESTRUCTURA FINANCIERA'!B48) -> 0.5644956 | D19: ='ESTRUCTURA FINANCIERA'!D56/('ESTRUCTURA FINANCIERA'!D56+'ESTRUCTURA FINANCIERA'!D48) -> 0.59743629 | F19: ='ESTRUCTURA FINANCIERA'!F56/('ESTRUCTURA FINANCIERA'!F56+'ESTRUCTURA FINANCIERA'!F48) -> 0.61195566 | H19: ='ESTRUCTURA FINANCIERA'!H64/('ESTRUCTURA FINANCIERA'!H64+'ESTRUCTURA FINANCIERA'!H56) -> #DIV/0! | J19: ='ESTRUCTURA FINANCIERA'!J64/('ESTRUCTURA FINANCIERA'!J64+'ESTRUCTURA FINANCIERA'!J56) -> #DIV/0! | K19: #DIV/0!
A20: Índice de endeudamiento sin ajuste por inflación | B20: =('ESTRUCTURA FINANCIERA'!B49+'ESTRUCTURA FINANCIERA'!B55)/'ESTRUCTURA FINANCIERA'!B30 -> 0.93220194 | D20: =('ESTRUCTURA FINANCIERA'!D49+'ESTRUCTURA FINANCIERA'!D55)/'ESTRUCTURA FINANCIERA'!D30 -> 0.92698691 | F20: =('ESTRUCTURA FINANCIERA'!F49+'ESTRUCTURA FINANCIERA'!F55)/'ESTRUCTURA FINANCIERA'!F30 -> 0.94346921
A21: Índice de autonomía sin ajuste por inflación | B21: =('ESTRUCTURA FINANCIERA'!B56-'ESTRUCTURA FINANCIERA'!B55)/'ESTRUCTURA FINANCIERA'!B30 -> 0.06779806 | D21: =('ESTRUCTURA FINANCIERA'!D56-'ESTRUCTURA FINANCIERA'!D55)/'ESTRUCTURA FINANCIERA'!D30 -> 0.073013087 | F21: =('ESTRUCTURA FINANCIERA'!F56-'ESTRUCTURA FINANCIERA'!F55)/'ESTRUCTURA FINANCIERA'!F30 -> 0.056530788
A22: Apalancamiento externo sin ajuste por inflación | B22: =('ESTRUCTURA FINANCIERA'!B49)/('ESTRUCTURA FINANCIERA'!B56-'ESTRUCTURA FINANCIERA'!B55) -> 13.749684 | D22: =('ESTRUCTURA FINANCIERA'!D49)/('ESTRUCTURA FINANCIERA'!D56-'ESTRUCTURA FINANCIERA'!D55) -> 12.696175 | F22: =('ESTRUCTURA FINANCIERA'!F49)/('ESTRUCTURA FINANCIERA'!F56-'ESTRUCTURA FINANCIERA'!F55) -> 16.689476
A23: Apalancamiento interno sin ajuste por inflación | B23: =('ESTRUCTURA FINANCIERA'!B56-'ESTRUCTURA FINANCIERA'!B55)/'ESTRUCTURA FINANCIERA'!B49 -> 0.072728942 | D23: =('ESTRUCTURA FINANCIERA'!D56-'ESTRUCTURA FINANCIERA'!D55)/'ESTRUCTURA FINANCIERA'!D49 -> 0.078763881 | F23: =('ESTRUCTURA FINANCIERA'!F56-'ESTRUCTURA FINANCIERA'!F55)/'ESTRUCTURA FINANCIERA'!F49 -> 0.059917999
A24: Capitalizacion externa sin ajuste por inflación | B24: ='ESTRUCTURA FINANCIERA'!B48/('ESTRUCTURA FINANCIERA'!B56+'ESTRUCTURA FINANCIERA'!B48-'ESTRUCTURA FINANCIERA'!B55) -> 0.4355044 | D24: ='ESTRUCTURA FINANCIERA'!D48/('ESTRUCTURA FINANCIERA'!D56+'ESTRUCTURA FINANCIERA'!D48-'ESTRUCTURA FINANCIERA'!D55) -> 0.40256371 | F24: ='ESTRUCTURA FINANCIERA'!F48/('ESTRUCTURA FINANCIERA'!F56+'ESTRUCTURA FINANCIERA'!F48-'ESTRUCTURA FINANCIERA'!F55) -> 0.38804434
A25: Capitalizacion interna sin ajuste por inflación | B25: =('ESTRUCTURA FINANCIERA'!B56-'ESTRUCTURA FINANCIERA'!B55)/('ESTRUCTURA FINANCIERA'!B56+'ESTRUCTURA FINANCIERA'!B48-'ESTRUCTURA FINANCIERA'!B55) -> 0.5644956 | D25: =('ESTRUCTURA FINANCIERA'!D56-'ESTRUCTURA FINANCIERA'!D55)/('ESTRUCTURA FINANCIERA'!D56+'ESTRUCTURA FINANCIERA'!D48-'ESTRUCTURA FINANCIERA'!D55) -> 0.59743629 | F25: =('ESTRUCTURA FINANCIERA'!F56-'ESTRUCTURA FINANCIERA'!F55)/('ESTRUCTURA FINANCIERA'!F56+'ESTRUCTURA FINANCIERA'!F48-'ESTRUCTURA FINANCIERA'!F55) -> 0.61195566
A27: ACTIVIDAD | B27: =B4 -> 45657 | D27: =D4 -> 45291 | F27: =F4 -> 44926 | H27: =H4 -> 0 | J27: =J4 -> 0 | K27: =K4 -> 0
A28: Rotación de Inventarios | B28: ='ESTRUCTURA ECONOMICA'!B15/'ESTRUCTURA FINANCIERA'!B15 -> 227.7525 | D28: ='ESTRUCTURA ECONOMICA'!E15/'ESTRUCTURA FINANCIERA'!D15 -> 48.296658 | F28: ='ESTRUCTURA ECONOMICA'!G15/'ESTRUCTURA FINANCIERA'!F15 -> 24.228848 | H28: ='ESTRUCTURA ECONOMICA'!H10/'ESTRUCTURA ECONOMICA'!H15 -> 1.5891692 | J28: ='ESTRUCTURA ECONOMICA'!J15/'ESTRUCTURA ECONOMICA'!J23 -> #DIV/0! | K28: #DIV/0!
A29: Días de Inventario | B29: =IF('CAPITAL DE TRABAJO'!AL7=2,365,30)/B28 -> 0.13172194 | D29: =IF('CAPITAL DE TRABAJO'!AL7=2,365,30)/D28 -> 0.62116099 | F29: =IF('CAPITAL DE TRABAJO'!AL7=2,365,30)/F28 -> 1.2381934 | H29: =360/H28 -> 226.53346 | J29: =360/J28 -> #DIV/0! | K29: =360/K28 -> #DIV/0!
A30: Rotacion de cuentas por cobrar | B30: ='ESTRUCTURA ECONOMICA'!B10/('ESTRUCTURA FINANCIERA'!B12+'ESTRUCTURA FINANCIERA'!B13) -> 0.18725342 | D30: ='ESTRUCTURA ECONOMICA'!E10/('ESTRUCTURA FINANCIERA'!D12+'ESTRUCTURA FINANCIERA'!D13) -> 0.19643124 | F30: ='ESTRUCTURA ECONOMICA'!G10/('ESTRUCTURA FINANCIERA'!F12+'ESTRUCTURA FINANCIERA'!F13) -> 0.16268339 | H30: ='ESTRUCTURA ECONOMICA'!I15/'ESTRUCTURA FINANCIERA'!H19 -> #DIV/0! | J30: ='ESTRUCTURA ECONOMICA'!K15/'ESTRUCTURA FINANCIERA'!J19 -> #DIV/0! | K30: #DIV/0!
A31: Días de cuentas por cobrar | B31: =IF('CAPITAL DE TRABAJO'!AL7=2,365,30)/B30 -> 160.21069 | D31: =IF('CAPITAL DE TRABAJO'!AL7=2,365,30)/D30 -> 152.7252 | F31: =IF('CAPITAL DE TRABAJO'!AL7=2,365,30)/F30 -> 184.40727 | H31: =360/H30 -> #DIV/0! | J31: =360/J30 -> #DIV/0! | K31: =360/K30 -> #DIV/0!
A32: Rotación del activo fijo | B32: ='ESTRUCTURA ECONOMICA'!B10/'ESTRUCTURA FINANCIERA'!B23 -> 18.347637 | D32: ='ESTRUCTURA ECONOMICA'!E10/'ESTRUCTURA FINANCIERA'!D23 -> 17.686096 | F32: ='ESTRUCTURA ECONOMICA'!G10/'ESTRUCTURA FINANCIERA'!F23 -> 15.972827 | H32: ='ESTRUCTURA ECONOMICA'!J15/'ESTRUCTURA FINANCIERA'!H30 -> #DIV/0! | J32: ='ESTRUCTURA ECONOMICA'!M15/'ESTRUCTURA FINANCIERA'!J30 -> #DIV/0! | K32: #DIV/0!
A33: Rotación del activo total | B33: ='ESTRUCTURA ECONOMICA'!B10/'ESTRUCTURA FINANCIERA'!B30 -> 0.10528413 | D33: ='ESTRUCTURA ECONOMICA'!E10/'ESTRUCTURA FINANCIERA'!D30 -> 0.10819498 | F33: ='ESTRUCTURA ECONOMICA'!G10/'ESTRUCTURA FINANCIERA'!F30 -> 0.084992879 | H33: ='ESTRUCTURA ECONOMICA'!J15/'ESTRUCTURA FINANCIERA'!H38 -> #DIV/0! | J33: ='ESTRUCTURA ECONOMICA'!M15/'ESTRUCTURA FINANCIERA'!J38 -> #DIV/0! | K33: #DIV/0!
A34: Rotación del Capital de Trabajo | B34: ='ESTRUCTURA ECONOMICA'!B10/INDICES!B5 -> 1.0005764 | D34: ='ESTRUCTURA ECONOMICA'!E10/INDICES!D5 -> 1.0350946 | F34: ='ESTRUCTURA ECONOMICA'!G10/INDICES!F5 -> 1.123209 | H34: ='ESTRUCTURA ECONOMICA'!I15/INDICES!H5 -> #DIV/0! | J34: ='ESTRUCTURA ECONOMICA'!K15/INDICES!J5 -> #DIV/0! | K34: #DIV/0!
A35: Período de pago | B35: =('ESTRUCTURA FINANCIERA'!B33+'ESTRUCTURA FINANCIERA'!B34)/('ESTRUCTURA ECONOMICA'!B15/IF('CAPITAL DE TRABAJO'!AL7=2,365,30)) -> 74.926663 | D35: =('ESTRUCTURA FINANCIERA'!D33+'ESTRUCTURA FINANCIERA'!D34)/('ESTRUCTURA ECONOMICA'!E15/IF('CAPITAL DE TRABAJO'!AL7=2,365,30)) -> 55.662258 | F35: =('ESTRUCTURA FINANCIERA'!F33+'ESTRUCTURA FINANCIERA'!F34)/('ESTRUCTURA ECONOMICA'!G15/IF('CAPITAL DE TRABAJO'!AL7=2,365,30)) -> 108.02609 | H35: =360/H30 -> #DIV/0! | J35: =360/J30 -> #DIV/0! | K35: #DIV/0!
A36: Ciclo Económico de caja | B36: =(('ESTRUCTURA FINANCIERA'!B15/('ESTRUCTURA ECONOMICA'!B10/IF('CAPITAL DE TRABAJO'!AL7=2,365,30)))+((('ESTRUCTURA FINANCIERA'!B12+'ESTRUCTURA FINANCIERA'!B13)/('ESTRUCTURA ECONOMICA'!B10/IF('CAPITAL DE TRABAJO'!AL7=2,365,30))))-(('ESTRUCTURA FINANCIERA'!B33+'ESTRUCTURA FINANCIERA'!B34)/('ESTRUCTURA ECONOMICA'!B10/IF('CAPITAL DE TRABAJO'!AL7=2,365,30)))) -> 113.93699 | D36: =(('ESTRUCTURA FINANCIERA'!D15/('ESTRUCTURA ECONOMICA'!E10/IF('CAPITAL DE TRABAJO'!AL7=2,365,30)))+((('ESTRUCTURA FINANCIERA'!D12+'ESTRUCTURA FINANCIERA'!D13)/('ESTRUCTURA ECONOMICA'!E10/IF('CAPITAL DE TRABAJO'!AL7=2,365,30))))-(('ESTRUCTURA FINANCIERA'!D33+'ESTRUCTURA FINANCIERA'!D34)/('ESTRUCTURA ECONOMICA'!E10/IF('CAPITAL DE TRABAJO'!AL7=2,365,30)))) -> 119.10749 | F36: =(('ESTRUCTURA FINANCIERA'!F15/('ESTRUCTURA ECONOMICA'!G10/IF('CAPITAL DE TRABAJO'!AL7=2,365,30)))+((('ESTRUCTURA FINANCIERA'!F12+'ESTRUCTURA FINANCIERA'!F13)/('ESTRUCTURA ECONOMICA'!G10/IF('CAPITAL DE TRABAJO'!AL7=2,365,30))))-(('ESTRUCTURA FINANCIERA'!F33+'ESTRUCTURA FINANCIERA'!F34)/('ESTRUCTURA ECONOMICA'!G10/IF('CAPITAL DE TRABAJO'!AL7=2,365,30)))) -> 117.20997 | H36: =H29+H31-H35 -> #DIV/0! | J36: =J29+J31-J35 -> #DIV/0! | K36: =+K31-K35 -> #DIV/0!
A38: RENTABILIDAD | B38: =B4 -> 45657 | D38: =D4 -> 45291 | F38: =F4 -> 44926 | H38: =H4 -> 0 | J38: =J4 -> 0 | K38: =K4 -> 0
A39: Margen de Utilidad Bruta | B39: ='ESTRUCTURA ECONOMICA'!B16/'ESTRUCTURA ECONOMICA'!B10 -> 0.38132577 | D39: ='ESTRUCTURA ECONOMICA'!E16/'ESTRUCTURA ECONOMICA'!E10 -> 0.38922532 | F39: ='ESTRUCTURA ECONOMICA'!G16/'ESTRUCTURA ECONOMICA'!G10 -> 0.3707404 | H39: ='ESTRUCTURA ECONOMICA'!I26/'ESTRUCTURA ECONOMICA'!I15 -> #DIV/0! | J39: ='ESTRUCTURA ECONOMICA'!K26/'ESTRUCTURA ECONOMICA'!K15 -> #DIV/0! | K39: #DIV/0!
A40: Margen de Utilidad en Operaciones | B40: ='ESTRUCTURA ECONOMICA'!B21/'ESTRUCTURA ECONOMICA'!B10 -> -0.29022718 | D40: ='ESTRUCTURA ECONOMICA'!E21/'ESTRUCTURA ECONOMICA'!E10 -> -0.24545097 | F40: ='ESTRUCTURA ECONOMICA'!G21/'ESTRUCTURA ECONOMICA'!G10 -> -0.29029491 | H40: ='ESTRUCTURA ECONOMICA'!I33/'ESTRUCTURA ECONOMICA'!I15 -> #DIV/0! | J40: ='ESTRUCTURA ECONOMICA'!K33/'ESTRUCTURA ECONOMICA'!K15 -> #DIV/0! | K40: #DIV/0!
A41: Margen de Utilidad Neta | B41: ='ESTRUCTURA ECONOMICA'!B31/'ESTRUCTURA ECONOMICA'!B10 -> 0.085388175 | D41: ='ESTRUCTURA ECONOMICA'!E31/'ESTRUCTURA ECONOMICA'!E10 -> 0.1054067 | F41: ='ESTRUCTURA ECONOMICA'!G31/'ESTRUCTURA ECONOMICA'!G10 -> 0.120356 | H41: ='ESTRUCTURA ECONOMICA'!I50/'ESTRUCTURA ECONOMICA'!I15 -> #DIV/0! | J41: ='ESTRUCTURA ECONOMICA'!K50/'ESTRUCTURA ECONOMICA'!K15 -> #DIV/0! | K41: #DIV/0!
A42: Rendimiento sobre activo fijo | B42: ='ESTRUCTURA ECONOMICA'!B31/'ESTRUCTURA FINANCIERA'!B23 -> 1.5666712 | D42: ='ESTRUCTURA ECONOMICA'!E31/'ESTRUCTURA FINANCIERA'!D23 -> 1.8642331 | F42: ='ESTRUCTURA ECONOMICA'!G31/'ESTRUCTURA FINANCIERA'!F23 -> 1.9224255 | H42: ='ESTRUCTURA ECONOMICA'!I50/'ESTRUCTURA FINANCIERA'!H30 -> #DIV/0! | J42: ='ESTRUCTURA ECONOMICA'!K50/'ESTRUCTURA FINANCIERA'!J30 -> #DIV/0! | K42: #DIV/0!
A43: Rendimiento sobre activo total | B43: ='ESTRUCTURA ECONOMICA'!B31/'ESTRUCTURA FINANCIERA'!B30 -> 0.0089900199 | D43: ='ESTRUCTURA ECONOMICA'!E31/'ESTRUCTURA FINANCIERA'!D30 -> 0.011404476 | F43: ='ESTRUCTURA ECONOMICA'!G31/'ESTRUCTURA FINANCIERA'!F30 -> 0.010229403 | H43: ='ESTRUCTURA ECONOMICA'!I50/'ESTRUCTURA FINANCIERA'!H38 -> #DIV/0! | J43: ='ESTRUCTURA ECONOMICA'!K50/'ESTRUCTURA FINANCIERA'!J38 -> #DIV/0! | K43: #DIV/0!
A44: Rendimiento sobre patrimonio | B44: ='ESTRUCTURA ECONOMICA'!B31/'ESTRUCTURA FINANCIERA'!B56 -> 0.13259996 | D44: ='ESTRUCTURA ECONOMICA'!E31/'ESTRUCTURA FINANCIERA'!D56 -> 0.1561977 | F44: ='ESTRUCTURA ECONOMICA'!G31/'ESTRUCTURA FINANCIERA'!F56 -> 0.18095277 | H44: ='ESTRUCTURA ECONOMICA'!I50/'ESTRUCTURA FINANCIERA'!H64 -> #DIV/0! | J44: ='ESTRUCTURA ECONOMICA'!K50/'ESTRUCTURA FINANCIERA'!J64 -> #DIV/0! | K44: #DIV/0!
A45: Rendimiento sobre Capital Empleado | B45: ='ESTRUCTURA ECONOMICA'!B31/('ESTRUCTURA FINANCIERA'!B56+'ESTRUCTURA FINANCIERA'!B49) -> 0.0089900199 | D45: ='ESTRUCTURA ECONOMICA'!E31/('ESTRUCTURA FINANCIERA'!D56+'ESTRUCTURA FINANCIERA'!D49) -> 0.011404476 | F45: ='ESTRUCTURA ECONOMICA'!G31/('ESTRUCTURA FINANCIERA'!F56+'ESTRUCTURA FINANCIERA'!F49) -> 0.010229403 | H45: ='ESTRUCTURA ECONOMICA'!I50/('ESTRUCTURA FINANCIERA'!H64+'ESTRUCTURA FINANCIERA'!H57) -> #DIV/0! | J45: ='ESTRUCTURA ECONOMICA'!K50/('ESTRUCTURA FINANCIERA'!J64+'ESTRUCTURA FINANCIERA'!J57) -> #DIV/0! | K45: #DIV/0!
A46: Rendimiento sobre Capital de Trabajo | B46: ='ESTRUCTURA ECONOMICA'!B31/INDICES!B5 -> 0.085437389 | D46: ='ESTRUCTURA ECONOMICA'!E31/INDICES!D5 -> 0.1091059 | F46: ='ESTRUCTURA ECONOMICA'!G31/INDICES!F5 -> 0.13518494 | H46: ='ESTRUCTURA ECONOMICA'!I50/INDICES!H5 -> #DIV/0! | J46: ='ESTRUCTURA ECONOMICA'!K50/INDICES!J5 -> #DIV/0! | K46: #DIV/0!
...

Sheet EVA
A1: Valor Económico Añadido
A2: Descripción | B2: 0 | C2: % | D2: 0 | E2: % | F2: 0 | G2: % | H2: 0 | J2: 0 | L2: ='RENTABILIDAD-BENEFICIOS'!B7 -> 45657 | N2: ='GENERACION DE RECURSOS'!$D$6 -> 45291 | P2: ='GENERACION DE RECURSOS'!$F$6 -> 44926 | R2: Descripción | S2: 0 | U2: 0 | W2: 0 | Y2: 0 | AA2: 0 | AC2: =L2 -> 45657 | AE2: =N2 -> 45291 | AG2: =P2 -> 44926
A3: ACTIVO CIRCULANTE | B3: 0 | C3: =B3/B5 -> #DIV/0! | D3: 0 | E3: =D3/D5 -> #DIV/0! | F3: 0 | G3: =F3/F5 -> #DIV/0! | H3: 0 | J3: 0 | L3: ='ESTRUCTURA FINANCIERA'!B17 -> 68276001781 | N3: ='ESTRUCTURA FINANCIERA'!D17 -> 54982369783 | P3: ='ESTRUCTURA FINANCIERA'!F17 -> 50414009559 | R3: EVA = NOPAT - WACC * FINANCING
A4: ACTIVO FIJO NETO | B4: 0 | C4: =B4/B5 -> #DIV/0! | D4: 0 | E4: =D4/D5 -> #DIV/0! | F4: 0 | G4: =F4/F5 -> #DIV/0! | H4: 0 | J4: 0 | L4: ='ESTRUCTURA FINANCIERA'!B29 -> 1031313965 | N4: ='ESTRUCTURA FINANCIERA'!D29 -> 989812227 | P4: ='ESTRUCTURA FINANCIERA'!F29 -> 856607398 | R4: Utilidad neta operacional | S4: =B17 -> 0 | U4: =D17 -> 0 | W4: =F17 -> 0 | Y4: =H17 -> 0 | AA4: =J17 -> 0 | AC4: =L17 -> 682548271 | AE4: =N17 -> 676981945 | AG4: =P17 -> 533435923
A5: TOTAL ACTIVOS | B5: =SUM(B3:B4) -> 0 | C5: =SUM(C3:C4) -> #DIV/0! | D5: =SUM(D3:D4) -> 0 | E5: =SUM(E3:E4) -> #DIV/0! | F5: =SUM(F3:F4) -> 0 | G5: =SUM(G3:G4) -> #DIV/0! | H5: =SUM(H3:H4) -> 0 | J5: =SUM(J3:J4) -> 0 | L5: =SUM(L3:L4) -> 69307315746 | N5: =SUM(N3:N4) -> 55972182010 | P5: =SUM(P3:P4) -> 51270616957 | R5: Impuesto sobre la renta | S5: =-S4*B10 -> 0 | U5: =-U4*D10 -> 0 | W5: =-W4*F10 -> 0 | Y5: =-Y4*H10 -> 0 | AA5: =-AA4*J10 -> 0 | AC5: =-AC4*L10 -> -59474126 | AE5: =-AE4*N10 -> -38648533 | AG5: =-AG4*P10 -> -8968137
R6: Utilidad neta operacional | S6: =SUM(S4:S5) -> 0 | U6: =SUM(U4:U5) -> 0 | W6: =SUM(W4:W5) -> 0 | Y6: =SUM(Y4:Y5) -> 0 | AA6: =SUM(AA4:AA5) -> 0 | AC6: =SUM(AC4:AC5) -> 623074145 | AE6: =SUM(AE4:AE5) -> 638333412 | AG6: =SUM(AG4:AG5) -> 524467786
